Workbook

Sheet Summary
A1: Billing run 1 Oct 2026 — cases to verify before generating invoices
A2: Read-only snapshot taken 30 Sep 2026 from the live CRM. Nothing has been changed. Verify each case tab, fill the yellow columns, and send the file back.
A4: Laptops on rent | C4: 3051
A5: Billed through 30 Sep (roll into October normally) | C5: 2738
A6: Delivered in September, never billed (billed Sept + Oct tomorrow) | C6: 192
A7: Billed only to a date before 30 Sep (catch-up tomorrow) | C7: 115
A9: Case | B9: Tab | C9: What | D9: Rows | E9: Amount (Rs) | F9: Risk if not handled | G9: Your decision (overall) | H9: Remarks
A10: 1 | B10: 1 PPG postpaid | C10: PPG postpaid August invoice (INV-0974) would be overwritten | D10: =COUNTA('1 PPG postpaid'!K13:K512) | E10: =SUM('1 PPG postpaid'!H13:H512) | F10: August invoice lost / September billed on the wrong invoice
A11: 2 | B11: 2 Double credit | C11: Returned laptops credited twice (20 credit notes) | D11: =COUNTA('2 Double credit'!L13:L512) | E11: =SUM('2 Double credit'!K13:K512) | F11: Customer gets the same returned days off twice
A12: 3 | B12: 3 Pending CNs | C12: Pending credit notes — 11 linked to already-sent invoices | D12: =COUNTA('3 Pending CNs'!M13:M512) | E12: =SUM('3 Pending CNs'!F13:F512) | F12: Credit never reaches the customer, or is applied late
A13: 4 | B13: 4 Repair pickups | C13: Repair pickups not billed as per agreed rule (29 laptops) | D13: =COUNTA('4 Repair pickups'!K13:K512) | E13: =SUM('4 Repair pickups'!H13:H512) | F13: October rent missed on repaired laptops / wrong return credit notes
A14: 5 | B14: 5 Sale orders | C14: Sold laptops set up as rented (TTSPL3059 Rs 20,000/month) | D14: =COUNTA('5 Sale orders'!K13:K512) | F14: Customer billed rent on a sold laptop
A15: 6 | B15: 6 Silent skips | C15: Laptops skipped: no rate / no start date / no TTSPL code | D15: =COUNTA('6 Silent skips'!K13:K512) | E15: =SUM('6 Silent skips'!G13:G512) | F15: Laptop not billed at all
A16: 7 | B16: 7 In transit | C16: Dispatched 26–30 Sep, billing starts 1 Oct (16 laptops) | D16: =COUNTA('7 In transit'!I13:I512) | E16: =SUM('7 In transit'!H13:H512) | F16: A few September days not billed; October billed before delivery
A17: 8 | B17: 8 Demo & Rs1 | C17: Demo / Rs 1 laptops with customers | D17: =COUNTA('8 Demo & Rs1'!J13:J512) | E17: =SUM('8 Demo & Rs1'!H13:H512) | F17: Rs 1 lines, or paid laptops billed Rs 1
A18: 9 | B18: 9 Linked not billed | C18: Customer-linked laptops in a non-billing status | D18: =COUNTA('9 Linked not billed'!H13:H512) | F18: Laptop at customer but not billed
A19: 10 | B19: 10 Rate differences | C19: Billed rate vs sales-order rate (32 laptops, 3 open) | D19: =COUNTA('10 Rate differences'!H13:H512) | F19: Wrong monthly amount
A20: 11 | B20: 11 TTSPL4114 | C20: Returned laptop still "rented" (TTSPL4114) | D20: =COUNTA('11 TTSPL4114'!I13:I512) | E20: =SUM('11 TTSPL4114'!G13:G512) | F20: Billed while not with customer
A21: 12 | B21: 12 Credit over total | C21: Credit larger than invoice — excess lost (2 invoices) | D21: =COUNTA('12 Credit over total'!K13:K512) | E21: =SUM('12 Credit over total'!J13:J512) | F21: Customer loses credit
A22: 13 | B22: 13 No GSTIN | C22: Customers without GSTIN (tax head defaults to Haryana) | D22: =COUNTA('13 No GSTIN'!F13:F512) | F22: Wrong tax head on invoice
A24: How to use: open each tab (click the tab name above), read "What this is" and "How to verify", check each row, then pick "Your decision" in the yellow column and add notes in "Remarks".
A25: Yellow cells are the only cells to fill. Red rows inside a tab are the most urgent ones.
A26: Example: tab "5 Sale orders", row TTSPL3059 → Your decision = "Sold — stop rent (fix)", Remarks = "free warranty replacement for TTSPL6191".
A27: "Amount" = sum of the money column of that tab (credit amount, monthly rate or invoice total — see the tab header). Rows = number of rows in the tab.
A28: Run order after your answers: 1) I apply approved fixes (dry-run + backup first) 2) run invoices ONCE 3) I check invoices and move case-3 credit notes 4) accounts approve credit notes while invoices are drafts, then send.
A29: Do not click "Generate invoices" again after the first run — re-running on drafts creates double credit (case 2).

Sheet 1 PPG postpaid
A1: Case 1 — PPG Asian Paints (postpaid): August invoice would be overwritten
A3: What this is | B3: PPG (customer 79) is the only postpaid customer: they are billed for the month that just ended. Their August invoice INV-0974 is still a DRAFT and is stored with invoice month 9. When the October run is started for "All customers", the system bills postpaid customers for September, finds INV-0974 (month 9, draft) and rebuilds it with September usage — August's invoice would be lost.
A5: How to verify (step by step) | B5: 1. Open Customer Billing → Invoices, filter customer PPG ASIAN PAINTS. 2. Open INV-0974: confirm it covers 1–31 Aug 2026 and the laptops/amount are what PPG should pay for August. 3. Confirm whether INV-0974 was already sent to PPG outside the CRM (email / Zoho). 4. Decide: send/finalise INV-0974 in the CRM today, so tomorrow's run creates a NEW invoice for September.
A7: Recommendation | B7: Send (or mark sent) INV-0974 today. I will then correct its month so tomorrow bills September separately. Do NOT run PPG alone with "customer list" for month 10 — that would bill October in advance.
A11: Fill the yellow columns: pick "Your decision" from the list, add anything else in "Remarks".
A12: Invoice | B12: Invoice month | C12: Year | D12: Status | E12: From | F12: To | G12: Subtotal (Rs) | H12: Grand total (Rs) | I12: Customer | J12: Billing type | K12: What to check for this row | L12: Your decision | M12: Remarks
A13: INV-0974 | B13: 9 | C13: 2026 | D13: draft | E13: 2026-08-01 | F13: 2026-08-31 | G13: 19676.25 | H13: 23217.97 | I13: PPG ASIAN PAINTS PRIVATE LIMITED | J13: postpaid | K13: August invoice stored as month 9 — confirm amount, then send/finalise it today.
A14: INV-0052 | B14: 7 | C14: 2026 | D14: draft | E14: 2026-07-01 | F14: 2026-07-31 | G14: 20985 | H14: 24762.3 | I14: PPG ASIAN PAINTS PRIVATE LIMITED | J14: postpaid | K14: Older PPG invoice (still draft) — confirm whether it was ever sent.

Sheet 2 Double credit
A1: Case 2 — Returned laptops credited twice (pending credit notes)
A3: What this is | B3: For each row the customer's invoice line ALREADY stops on the return date (invoice line "To" column), AND a pending credit note credits the days after it (credit note "From"–"To"). If accounts approves these credit notes, the customer gets the same days off twice. Cause: September drafts were regenerated after the returns.
A5: How to verify (step by step) | B5: 1. Open the invoice in the row; find the laptop (TTSPL) line and check its billing period ends on "Invoice line to". 2. Open the credit note in the row; check it credits "Credit note from" to "Credit note to" for the same laptop. 3. If the invoice line already stops at the return date, the credit note line is a duplicate. 4. Confirm the warehouse return date of the laptop (Return DC / RDC) matches the invoice line end date.
A7: Recommendation | B7: Cancel the duplicate credit-note lines (I can do it once you approve). Do NOT approve these credit notes as they are.
A11: Fill the yellow columns: pick "Your decision" from the list, add anything else in "Remarks".
A12: Credit note | B12: CN status | C12: Customer | D12: TTSPL | E12: Invoice | F12: Invoice status | G12: Invoice line from | H12: Invoice line to | I12: Credit note from | J12: Credit note to | K12: Credit amount (Rs) | L12: What to check for this row | M12: Your decision | N12: Remarks
A13: CN-0024 | B13: pending | C13: Beom Commerce Private Limited | D13: TTSPL4943 | E13: INV-1005 | F13: sent | G13: 2026-09-01 | H13: 2026-09-02 | I13: 2026-09-03 | J13: 2026-09-30 | K13: 886.67 | L13: Invoice INV-1005 already bills only to 2026-09-02; credit 2026-09-03→2026-09-30 repeats the days after. Duplicate?
A14: CN-0096 | B14: pending | C14: PERNIMIUS FINANCIAL TECHNOLOGIES PRIVATE LIMITED | D14: TTSPL3049 | E14: INV-1018 | F14: draft | G14: 2026-09-01 | H14: 2026-09-02 | I14: 2026-09-03 | J14: 2026-09-30 | K14: 1306.67 | L14: Invoice INV-1018 already bills only to 2026-09-02; credit 2026-09-03→2026-09-30 repeats the days after. Duplicate?
A15: CN-0246 | B15: pending | C15: SLEEP MANAGEMENT PRIVATE LIMITED | D15: TTSPL5167 | E15: INV-1014 | F15: draft | G15: 2026-09-01 | H15: 2026-09-03 | I15: 2026-09-04 | J15: 2026-09-30 | K15: 1799.1 | L15: Invoice INV-1014 already bills only to 2026-09-03; credit 2026-09-04→2026-09-30 repeats the days after. Duplicate?
A16: CN-0248 | B16: pending | C16: FLEET LABS TECHNOLOGIES PRIVATE LIMITED | D16: TTSPL4513 | E16: INV-1081 | F16: draft | G16: 2026-09-01 | H16: 2026-09-04 | I16: 2026-09-05 | J16: 2026-09-30 | K16: 2339.13 | L16: Invoice INV-1081 already bills only to 2026-09-04; credit 2026-09-05→2026-09-30 repeats the days after. Duplicate?
A17: CN-0248 | B17: pending | C17: FLEET LABS TECHNOLOGIES PRIVATE LIMITED | D17: TTSPL5116 | E17: INV-1081 | F17: draft | G17: 2026-09-01 | H17: 2026-09-04 | I17: 2026-09-05 | J17: 2026-09-30 | K17: 2165.8 | L17: Invoice INV-1081 already bills only to 2026-09-04; credit 2026-09-05→2026-09-30 repeats the days after. Duplicate?
A18: CN-0248 | B18: pending | C18: FLEET LABS TECHNOLOGIES PRIVATE LIMITED | D18: TTSPL6222 | E18: INV-1081 | F18: draft | G18: 2026-09-01 | H18: 2026-09-04 | I18: 2026-09-05 | J18: 2026-09-30 | K18: 1905.8 | L18: Invoice INV-1081 already bills only to 2026-09-04; credit 2026-09-05→2026-09-30 repeats the days after. Duplicate?
A19: CN-0248 | B19: pending | C19: FLEET LABS TECHNOLOGIES PRIVATE LIMITED | D19: TTSPL7043 | E19: INV-1081 | F19: draft | G19: 2026-09-01 | H19: 2026-09-04 | I19: 2026-09-05 | J19: 2026-09-30 | K19: 2339.13 | L19: Invoice INV-1081 already bills only to 2026-09-04; credit 2026-09-05→2026-09-30 repeats the days after. Duplicate?
A20: CN-0253 | B20: pending | C20: ASCENT RISK & RESILIENCE SOFTWARE PRIVATE LIMITED | D20: TTSPL4752 | E20: INV-1031 | F20: draft | G20: 2026-09-01 | H20: 2026-09-07 | I20: 2026-09-08 | J20: 2026-09-30 | K20: 2683.33 | L20: Invoice INV-1031 already bills only to 2026-09-07; credit 2026-09-08→2026-09-30 repeats the days after. Duplicate?
A21: CN-0253 | B21: pending | C21: ASCENT RISK & RESILIENCE SOFTWARE PRIVATE LIMITED | D21: TTSPL6511 | E21: INV-1031 | F21: draft | G21: 2026-09-01 | H21: 2026-09-08 | I21: 2026-09-09 | J21: 2026-09-30 | K21: 2565.93 | L21: Invoice INV-1031 already bills only to 2026-09-08; credit 2026-09-09→2026-09-30 repeats the days after. Duplicate?
A22: CN-0253 | B22: pending | C22: ASCENT RISK & RESILIENCE SOFTWARE PRIVATE LIMITED | D22: TTSPL6959 | E22: INV-1031 | F22: draft | G22: 2026-09-01 | H22: 2026-09-08 | I22: 2026-09-09 | J22: 2026-09-30 | K22: 2566.67 | L22: Invoice INV-1031 already bills only to 2026-09-08; credit 2026-09-09→2026-09-30 repeats the days after. Duplicate?
A23: CN-0255 | B23: pending | C23: ASCENT RISK & RESILIENCE SOFTWARE PRIVATE LIMITED | D23: TTSPL4940 | E23: INV-1031 | F23: draft | G23: 2026-09-01 | H23: 2026-09-09 | I23: 2026-09-10 | J23: 2026-09-30 | K23: 2449.3 | L23: Invoice INV-1031 already bills only to 2026-09-09; credit 2026-09-10→2026-09-30 repeats the days after. Duplicate?
A24: CN-0256 | B24: pending | C24: BIODEAL PHARMACEUTICALS LIMITED | D24: TTSPL6827 | E24: INV-1043 | F24: sent | G24: 2026-09-01 | H24: 2026-09-07 | I24: 2026-09-08 | J24: 2026-09-30 | K24: 1150 | L24: Invoice INV-1043 already bills only to 2026-09-07; credit 2026-09-08→2026-09-30 repeats the days after. Duplicate?
... A48: CN-0279 | B48: pending | C48: QUEST SOLUTIONS PRIVATE LIMITED | D48: TTSPL3876 | E48: INV-1125 | F48: sent | G48: 2026-09-01 | H48: 2026-09-23 | I48: 2026-09-24 | J48: 2026-09-30 | K48: 303.1 | L48: Invoice INV-1125 already bills only to 2026-09-23; credit 2026-09-24→2026-09-30 repeats the days after. Duplicate?

Sheet 3 Pending CNs
A1: Case 3 — All pending/approved credit notes (where each will land)
A3: What this is | B3: A credit note only reduces a bill when accounts APPROVES it while its linked invoice is still a DRAFT. Rows linked to a SENT invoice (red) can never reduce anything as things stand. Rows with no linked invoice go to the customer's latest draft when approved. "repair" type rows are the 5 credit notes that were not created by the live system (see case 4).
A5: How to verify (step by step) | B5: 1. For each credit note check the customer, laptop(s) (TTSPL list), period and amount are genuine. 2. Red rows: the linked September invoice is already sent — decide whether the credit should go on the October invoice. 3. Cross-check with case 2: credit notes listed there contain duplicate lines — decide those first. 4. Only approve after tomorrow's invoices are generated and while they are still drafts.
A7: Recommendation | B7: Red rows: move to the customer's October draft after the run, then approve. Others: approve after checking.
A11: Fill the yellow columns: pick "Your decision" from the list, add anything else in "Remarks".
A12: Credit note | B12: Status | C12: Type | D12: Source | E12: Customer | F12: Amount (Rs) | G12: From | H12: To | I12: TTSPL(s) | J12: Linked invoice | K12: Linked invoice status | L12: Created | M12: What to check for this row | N12: Your decision | O12: Remarks
A13: CN-0279 | B13: pending | C13: return | D13: invoice_generation | E13: QUEST SOLUTIONS PRIVATE LIMITED | F13: 303.1 | G13: 2026-09-24 | H13: 2026-09-30 | I13: TTSPL3876 | J13: INV-1125 | K13: sent | L13: 2026-09-24 | M13: Linked invoice already SENT — will never net. Move to October draft?
A14: CN-0258 | B14: pending | C14: return | D14: invoice_generation | E14: PIBIT TECHNOLOGIES PRIVATE LIMITED | F14: 19986.74 | G14: 2026-09-11 | H14: 2026-09-30 | I14: TTSPL4610, TTSPL7359, TTSPL7367, TTSPL7427, TTSPL7540, TTSPL7541, TTSPL5850 | J14: INV-1120 | K14: sent | L14: 2026-09-11 | M14: Linked invoice already SENT — will never net. Move to October draft?
A15: CN-0268 | B15: pending | C15: return | D15: invoice_generation | E15: Tekuncorked Aiiot Private Limited | F15: 719.6 | G15: 2026-09-19 | H15: 2026-09-30 | I15: TTSPL3789 | J15: INV-1163 | K15: sent | L15: 2026-09-18 | M15: Linked invoice already SENT — will never net. Move to October draft?
A16: CN-0275 | B16: pending | C16: return | D16: invoice_generation | E16: SGATE TECH SOLUTIONS PRIVATE LIMITED | F16: 949.5 | G16: 2026-09-16 | H16: 2026-09-30 | I16: TTSPL6376 | J16: INV-1142 | K16: sent | L16: 2026-09-22 | M16: Linked invoice already SENT — will never net. Move to October draft?
A17: CN-0259 | B17: pending | C17: return | D17: invoice_generation | E17: RHOPHI ANALYTICS LLP (Punjab) | F17: 8348.8 | G17: 2026-09-10 | H17: 2026-09-30 | I17: TTSPL5533, TTSPL5452 | J17: INV-1011 | K17: sent | L17: 2026-09-11 | M17: Linked invoice already SENT — will never net. Move to October draft?
A18: CN-0260 | B18: pending | C18: return | D18: invoice_generation | E18: LEEWAYHERTZ TECHNOLOGIES PRIVATE LIMITED | F18: 7124.5 | G18: 2026-09-12 | H18: 2026-09-30 | I18: TTSPL7018, TTSPL4018 | J18: INV-1013 | K18: sent | L18: 2026-09-12 | M18: Linked invoice already SENT — will never net. Move to October draft?
A19: CN-0024 | B19: pending | C19: return | D19: invoice_generation | E19: Beom Commerce Private Limited | F19: 886.67 | G19: 2026-09-03 | H19: 2026-09-30 | I19: TTSPL4943 | J19: INV-1005 | K19: sent | L19: 2026-09-02 | M19: Linked invoice already SENT — will never net. Move to October draft?
A20: CN-0256 | B20: pending | C20: return | D20: invoice_generation | E20: BIODEAL PHARMACEUTICALS LIMITED | F20: 1150 | G20: 2026-09-08 | H20: 2026-09-30 | I20: TTSPL6827 | J20: INV-1043 | K20: sent | L20: 2026-09-11 | M20: Linked invoice already SENT — will never net. Move to October draft?
A21: CN-0274 | B21: pending | C21: return | D21: invoice_generation | E21: BIODEAL PHARMACEUTICALS LIMITED | F21: 1200 | G21: 2026-09-18 | H21: 2026-09-30 | I21: TTSPL5496, TTSPL6630 | J21: INV-1043 | K21: sent | L21: 2026-09-22 | M21: Linked invoice already SENT — will never net. Move to October draft?
A22: CN-0261 | B22: pending | C22: return | D22: invoice_generation | E22: ZENITHIA GARDEN OF JOY PRIVATE LIMITED | F22: 699.5 | G22: 2026-09-16 | H22: 2026-09-30 | I22: TTSPL3186 | J22: INV-1182 | K22: sent | L22: 2026-09-15 | M22: Linked invoice already SENT — will never net. Move to October draft?
A23: CN-0266 | B23: pending | C23: return | D23: invoice_generation | E23: SPNN BUSINESS SERVICES PRIVATE LIMITED | F23: 1586.67 | G23: 2026-09-15 | H23: 2026-09-30 | I23: TTSPL6725, TTSPL3514 | J23: INV-1017 | K23: sent | L23: 2026-09-17 | M23: Linked invoice already SENT — will never net. Move to October draft?
A24: CN-0096 | B24: pending | C24: return | D24: invoice_generation | E24: PERNIMIUS FINANCIAL TECHNOLOGIES PRIVATE LIMITED | F24: 1306.67 | G24: 2026-09-03 | H24: 2026-09-30 | I24: TTSPL3049 | J24: INV-1018 | K24: draft | L24: 2026-09-02 | M24: Linked to a draft — nets when approved.
... A33: CN-0263 | B33: pending | C33: return | D33: invoice_generation | E33: DROR SERVICES PRIVATE LIMITED | F33: 1012.7 | G33: 2026-09-12 | H33: 2026-09-30 | I33: TTSPL6500 | J33: INV-1065 | K33: draft | L33: 2026-09-16 | M33: Linked to a draft — nets when approved.
A34: CN-0278 | B34: pending | C34: return | D34: invoice_generation | E34: Mercury Solutions Limited | F34: 509.7 | G34: 2026-09-22 | H34: 2026-09-30 | I34: TTSPL6664 | L34: 2026-09-24 | M34: Not linked yet — nets into the latest draft when approved.
A35: CN-0282 | B35: pending | C35: repair | D35: repair_window | E35: Mercury Solutions Limited | F35: 396.43 | G35: 2026-09-10 | H35: 2026-09-16 | I35: TTSPL3552 | L35: 2026-09-26 | M35: Not linked yet — nets into the latest draft when approved. (repair-type note: origin unknown, see case 4)
A36: CN-0281 | B36: pending | C36: return | D36: invoice_generation | E36: Upila Digital | F36: 833 | G36: 2026-09-26 | H36: 2026-09-30 | I36: TTSPL4967, TTSPL7179 | L36: 2026-09-26 | M36: Not linked yet — nets into the latest draft when approved.
A37: CN-0280 | B37: pending | C37: return | D37: invoice_generation | E37: PIBIT TECHNOLOGIES PRIVATE LIMITED | F37: 2049.6 | G37: 2026-09-25 | H37: 2026-09-30 | I37: TTSPL3203, TTSPL7344, TTSPL7463 | L37: 2026-09-25 | M37: Not linked yet — nets into the latest draft when approved.
A38: CN-0283 | B38: pending | C38: repair | D38: repair_window | E38: LEEWAYHERTZ TECHNOLOGIES PRIVATE LIMITED | F38: 94.97 | G38: 2026-09-16 | H38: 2026-09-16 | I38: TTSPL3731 | L38: 2026-09-26 | M38: Not linked yet — nets into the latest draft when approved. (repair-type note: origin unknown, see case 4)
A39: CN-0284 | B39: pending | C39: repair | D39: repair_window | E39: LEEWAYHERTZ TECHNOLOGIES PRIVATE LIMITED | F39: 94.97 | G39: 2026-09-24 | H39: 2026-09-24 | I39: TTSPL4019 | L39: 2026-09-26 | M39: Not linked yet — nets into the latest draft when approved. (repair-type note: origin unknown, see case 4)
A40: CN-0286 | B40: pending | C40: repair | D40: repair_window | E40: LEEWAYHERTZ TECHNOLOGIES PRIVATE LIMITED | F40: 114.97 | G40: 2026-09-24 | H40: 2026-09-24 | I40: TTSPL4515 | L40: 2026-09-26 | M40: Not linked yet — nets into the latest draft when approved. (repair-type note: origin unknown, see case 4)
A41: CN-0273 | B41: pending | C41: return | D41: invoice_generation | E41: RATHAM TECHNOLOGIES LLP | F41: 540 | G41: 2026-09-22 | H41: 2026-09-30 | I41: TTSPL4690 | L41: 2026-09-21 | M41: Not linked yet — nets into the latest draft when approved.
A42: CN-0285 | B42: pending | C42: repair | D42: repair_window | E42: RATHAM TECHNOLOGIES LLP | F42: 120 | G42: 2026-09-17 | H42: 2026-09-18 | I42: TTSPL4053 | L42: 2026-09-26 | M42: Not linked yet — nets into the latest draft when approved. (repair-type note: origin unknown, see case 4)
A43: CN-0272 | B43: pending | C43: return | D43: manual | E43: XSKY LOUNGE HOSPITALITY PRIVATE LIMITED | F43: 4445.14 | G43: 2026-07-01 | H43: 2026-09-30 | I43: TTSPL4801 | L43: 2026-09-21 | M43: Not linked yet — nets into the latest draft when approved.
A44: CN-0270 | B44: pending | C44: return | D44: return_pickup | E44: ABJAYON CONSULTANCY PRIVATE LIMITED | F44: 659.4 | G44: 2026-09-22 | H44: 2026-09-30 | I44: TTSPL6653 | L44: 2026-09-21 | M44: Not linked yet — nets into the latest draft when approved.
A45: CN-0271 | B45: pending | C45: return | D45: return_pickup | E45: ALLYVENTURE (INDIA) PRIVATE LIMITED | F45: 599.7 | G45: 2026-09-22 | H45: 2026-09-30 | I45: TTSPL6659 | L45: 2026-09-21 | M45: Not linked yet — nets into the latest draft when approved.

Sheet 4 Repair pickups
A1: Case 4 — Laptops picked up for repair (agreed rule vs what the system does)
A3: What this is | B3: Your agreed rule: during a repair the SAME laptop keeps billing; the warehouse days become a PENDING repair credit note for accounts to approve. The live system instead stops rent on the pickup date and removes the customer from the laptop, so these laptops will NOT be billed for October, and the run may create normal "return" credit notes for some (TTSPL4837, 7426, 4405, 5391, 6580, 7548). Laptops already back with the customer on a Service DC (SDC) resume billing from their new delivery.
A5: How to verify (step by step) | B5: 1. For each laptop confirm with support: was it a REPAIR (same laptop returns) or was it REPLACED by another laptop? 2. If replaced: rent correctly stops at the warehouse received date — nothing to add. 3. If repaired and already sent back (Service DC filled): confirm the laptop is with the customer and rent resumed. 4. If repaired and still at the warehouse: per your rule the customer should still be billed; note the days at warehouse (credit candidate). 5. Check "Billed until": days between billed-until and today that the customer should pay but will not be billed.
A7: Recommendation | B7: For this month choose per row: bill manually per your rule, or accept the system (rent stopped). The 5 "repair" credit notes at the bottom of case 3 were not created by the live system — confirm whether they are genuine.
A11: Fill the yellow columns: pick "Your decision" from the list, add anything else in "Remarks".
A12: TTSPL | B12: Current status | C12: Customer (pickup) | D12: Return DC | E12: Warehouse received | F12: Service DC (sent back) | G12: Still linked to customer | H12: Monthly rate (Rs) | I12: Billed until | J12: Rent end date | K12: What to check for this row | L12: Your decision | M12: Remarks
A13: TTSPL3203 | B13: returned | C13: PIBIT TECHNOLOGIES PRIVATE LIMITED | D13: RDC002329 | E13: 2026-09-24 | H13: 3174 | I13: 2026-09-30 | J13: 2026-09-24 | K13: Now returned at warehouse — repair or replacement? If repair, customer should still be billed.
A14: TTSPL4626 | B14: returned | C14: LEEWAYHERTZ TECHNOLOGIES PRIVATE LIMITED | D14: RDC002393 | H14: 2849 | I14: 2026-09-30 | J14: 2026-09-30 | K14: Now returned at warehouse — repair or replacement? If repair, customer should still be billed.
A15: TTSPL4405 | B15: returned | C15: ANTINO LABS PRIVATE LIMITED | D15: RDC002270 | E15: 2026-09-14 | H15: 1999 | I15: 2026-09-30 | J15: 2026-09-14 | K15: Now returned at warehouse — repair or replacement? If repair, customer should still be billed.
A16: TTSPL4940 | B16: returned | C16: ASCENT RISK & RESILIENCE SOFTWARE PRIVATE LIMITED | D16: RDC002228 | E16: 2026-09-09 | H16: 3499 | I16: 2026-09-09 | J16: 2026-09-09 | K16: Now returned at warehouse — repair or replacement? If repair, customer should still be billed.
A17: TTSPL3789 | B17: returned | C17: Tekuncorked Aiiot Private Limited | D17: RDC002303 | E17: 2026-09-18 | F17: SDC/26-27/0007 | H17: 1799 | K17: Sent back on SDC/26-27/0007 — confirm with customer and billing resumed.
A18: TTSPL3734 | B18: in_stock | C18: ASCENT RISK & RESILIENCE SOFTWARE PRIVATE LIMITED | D18: RDC002130 | E18: 2026-08-25 | H18: 3999 | I18: 2026-08-31 | J18: 2026-08-25 | K18: Now in_stock at warehouse — repair or replacement? If repair, customer should still be billed.
A19: TTSPL3731 | B19: in_stock | C19: LEEWAYHERTZ TECHNOLOGIES PRIVATE LIMITED | D19: RDC002284 | E19: 2026-09-15 | F19: SDC/26-27/0004 | H19: 2849 | K19: Sent back on SDC/26-27/0004 — confirm with customer and billing resumed.
A20: TTSPL4935 | B20: returned | C20: STEFEN ELECTRIC PRIVATE LIMIED | D20: RDC002223 | E20: 2026-09-09 | H20: 999 | I20: 2026-09-09 | J20: 2026-09-08 | K20: Now returned at warehouse — repair or replacement? If repair, customer should still be billed.
A21: TTSPL5391 | B21: returned | C21: BIODEAL PHARMACEUTICALS LIMITED | D21: RDC002370 | E21: 2026-09-29 | H21: 1500 | I21: 2026-09-30 | J21: 2026-09-28 | K21: Now returned at warehouse — repair or replacement? If repair, customer should still be billed.
A22: TTSPL6825 | B22: returned | C22: BIODEAL PHARMACEUTICALS LIMITED | D22: RDC002382 | E22: 2026-09-30 | H22: 1500 | I22: 2026-09-30 | J22: 2026-09-29 | K22: Now returned at warehouse — repair or replacement? If repair, customer should still be billed.
A23: TTSPL6827 | B23: returned | C23: BIODEAL PHARMACEUTICALS LIMITED | D23: RDC002205 | E23: 2026-09-07 | H23: 1500 | I23: 2026-09-07 | J23: 2026-09-05 | K23: Now returned at warehouse — repair or replacement? If repair, customer should still be billed.
A24: TTSPL5452 | B24: in_repair | C24: RHOPHI ANALYTICS LLP (Punjab) | D24: RDC002275 | E24: 2026-09-15 | H24: 8999 | I24: 2026-09-15 | J24: 2026-09-14 | K24: Now in_repair at warehouse — repair or replacement? If repair, customer should still be billed.
A25: TTSPL6009 | B25: scrapped | C25: SLEEP MANAGEMENT PRIVATE LIMITED | D25: RDC002101 | E25: 2026-08-20 | H25: 1999 | K25: Now scrapped at warehouse — repair or replacement? If repair, customer should still be billed.
A26: TTSPL6249 | B26: in_stock | C26: KULSYS TECHNOLOGIES PRIVATE LIMITED | D26: RDC002051 | E26: 2026-08-18 | H26: 3500 | I26: 2026-08-31 | J26: 2026-08-17 | K26: Now in_stock at warehouse — repair or replacement? If repair, customer should still be billed.
A27: TTSPL6580 | B27: in_stock | C27: BIODEAL PHARMACEUTICALS LIMITED | D27: RDC002325 | E27: 2026-09-23 | H27: 1500 | K27: Now in_stock at warehouse — repair or replacement? If repair, customer should still be billed.
A28: TTSPL6630 | B28: returned | C28: BIODEAL PHARMACEUTICALS LIMITED | D28: RDC002310 | E28: 2026-09-19 | H28: 1500 | I28: 2026-09-19 | J28: 2026-09-19 | K28: Now returned at warehouse — repair or replacement? If repair, customer should still be billed.
A29: TTSPL5449 | B29: rented | C29: Stylework Innovation Hub Pvt Ltd. | D29: RDC002374 | E29: 2026-09-29 | G29: 256 | H29: 1699 | K29: Now rented at warehouse — repair or replacement? If repair, customer should still be billed.
A30: TTSPL6376 | B30: returned | C30: SGATE TECH SOLUTIONS PRIVATE LIMITED | D30: RDC002283 | E30: 2026-09-15 | H30: 1899 | I30: 2026-09-15 | J30: 2026-09-15 | K30: Now returned at warehouse — repair or replacement? If repair, customer should still be billed.
A31: TTSPL6403 | B31: in_stock | C31: BIODEAL PHARMACEUTICALS LIMITED | D31: RDC002289 | E31: 2026-09-17 | F31: SDC/26-27/0005 | H31: 1500 | K31: Sent back on SDC/26-27/0005 — confirm with customer and billing resumed.
A32: TTSPL4837 | B32: returned | C32: NUTRITIONALAB PRIVATE LIMITED | D32: RDC002307 | E32: 2026-09-18 | H32: 2999 | I32: 2026-09-30 | J32: 2026-09-18 | K32: Now returned at warehouse — repair or replacement? If repair, customer should still be billed.
A33: TTSPL6926 | B33: returned | C33: Dotnova Aitech Private Limited | D33: RDC002347 | E33: 2026-09-24 | F33: SDC/26-27/0017 | H33: 3500 | K33: Sent back on SDC/26-27/0017 — confirm with customer and billing resumed.
A34: TTSPL1457 | B34: returned | C34: COAL BEAUTY PRIVATE LIMITED | D34: RDC002380 | E34: 2026-09-30 | H34: 1199 | I34: 2026-09-30 | J34: 2026-09-29 | K34: Now returned at warehouse — repair or replacement? If repair, customer should still be billed.
A35: TTSPL7344 | B35: returned | C35: PIBIT TECHNOLOGIES PRIVATE LIMITED | D35: RDC002233 | E35: 2026-09-24 | H35: 3174 | I35: 2026-09-30 | J35: 2026-09-24 | K35: Now returned at warehouse — repair or replacement? If repair, customer should still be billed.
A36: TTSPL7426 | B36: in_stock | C36: PIBIT TECHNOLOGIES PRIVATE LIMITED | D36: RDC002341 | E36: 2026-09-26 | H36: 4200 | K36: Now in_stock at warehouse — repair or replacement? If repair, customer should still be billed.
A37: TTSPL7463 | B37: returned | C37: PIBIT TECHNOLOGIES PRIVATE LIMITED | D37: RDC002320 | E37: 2026-09-24 | H37: 3900 | I37: 2026-09-30 | J37: 2026-09-24 | K37: Now returned at warehouse — repair or replacement? If repair, customer should still be billed.
A38: TTSPL7540 | B38: returned | C38: PIBIT TECHNOLOGIES PRIVATE LIMITED | D38: RDC002209 | E38: 2026-09-10 | H38: 3900 | I38: 2026-09-10 | J38: 2026-09-10 | K38: Now returned at warehouse — repair or replacement? If repair, customer should still be billed.
A39: TTSPL7547 | B39: reserved | C39: Khelo Tech and Strategy Pvt Ltd | D39: RDC002068 | E39: 2026-08-19 | F39: SDC/26-27/0003 | G39: 969 | H39: 2599 | I39: 2026-08-31 | J39: 2026-08-18 | K39: Sent back on SDC/26-27/0003 — confirm with customer and billing resumed.
A40: TTSPL7548 | B40: in_stock | C40: Khelo Tech and Strategy Pvt Ltd | D40: RDC002215 | E40: 2026-09-14 | H40: 2599 | K40: Now in_stock at warehouse — repair or replacement? If repair, customer should still be billed.
A41: TTSPL6191 | B41: returned | C41: RRA Project Management Private Limited | D41: RDC002165 | E41: 2026-08-31 | H41: 20000 | J41: 2026-08-31 | K41: Now returned at warehouse — repair or replacement? If repair, customer should still be billed.

Sheet 5 Sale orders
A1: Case 5 — Laptops on SALE orders that are still set up as rented
A3: What this is | B3: A sold laptop must never get a monthly rent bill. TTSPL3059 is the warranty replacement for sold laptop TTSPL6191 (RRA Project Management). It sits on a sale order but is "rented" at Rs 20,000/month, so tomorrow it would be billed about Rs 38,000 + GST (4–30 Sep + October). Serial 3749 (PG02Y0BH, Notus Services) is on sale order SO-003719 but is "rented" at Rs 1,800/month. TTSPL1479 / TTSPL1803 are sale units already returned (no customer) — not billed.
A5: How to verify (step by step) | B5: 1. TTSPL3059: confirm it is the free warranty replacement of the sold TTSPL6191 (no rent should be charged). 2. Serial 3749 / PG02Y0BH: confirm whether Notus BOUGHT it (sale) or RENTS it at Rs 1,800/month. 3. Check whether Notus has been paying Rs 1,800 monthly for serial 3749 (earlier invoices). 4. TTSPL1479 / TTSPL1803: confirm they are back in our warehouse (sale reversed/returned).
A7: Recommendation | B7: TTSPL3059: run the prepared fix (move to original sale order at Rs 0, mark sold) before billing. Serial 3749: your decision.
A11: Fill the yellow columns: pick "Your decision" from the list, add anything else in "Remarks".
A12: TTSPL | B12: Serial | C12: Status | D12: Customer | E12: Current DC | F12: Sales order | G12: Order type | H12: Order rate (Rs) | I12: Monthly rent rate (Rs) | J12: Billed until | K12: What to check for this row | L12: Your decision | M12: Remarks
A13: TTSPL1479 | B13: F51RF12 | C13: returned | E13: DC-003656 | F13: SO-003752 | G13: sale | H13: 8474 | K13: Returned sale unit — confirm it is back in warehouse.
A14: TTSPL1803 | B14: H549HC2 | C14: returned | E14: DC-003562 | F14: SO-003645 | G14: sale | H14: 13593 | K14: Returned sale unit — confirm it is back in warehouse.
B15: PG02Y0BH | C15: rented | D15: NOTUS SERVICES PRIVATE LIMITED | E15: DC-003631 | F15: SO-003719 | G15: sale | H15: 19492 | I15: 1800 | J15: 2026-09-30 | K15: Sale order but billed Rs 1,800/month — sold or rented?
A16: TTSPL3059 | C16: rented | D16: RRA Project Management Private Limited | E16: DC/26-27/1268 | F16: SO/26-27/1292 | G16: sale | H16: 1 | I16: 20000 | J16: 2026-08-31 | K16: Would be billed ~Rs 38,000 + GST tomorrow. Confirm it is a free warranty replacement.

Sheet 6 Silent skips
A1: Case 6 — Laptops with a customer that the run will skip without warning
A3: What this is | B3: These laptops are with a customer but are missing a monthly rate, a rent start date, or a TTSPL code, so the run skips them (or cannot match their delivery/return). They will NOT appear on any invoice tomorrow.
A5: How to verify (step by step) | B5: 1. Find the laptop by serial / TTSPL with the customer (DC in "Current DC"). 2. No rate: take the monthly rate from the customer's sales order / agreement. 3. No rent start date: take the delivery date from the DC (courier: delivery date or dispatch + 3 days, whichever is earlier). 4. No TTSPL code: confirm the physical asset tag on the laptop; tell me the TTSPL code. 5. If the laptop is NOT actually with this customer any more, say so (it will be removed from the customer).
A7: Recommendation | B7: Give me the missing value per row (Remarks column); I will set it before the run so these are billed.
A11: Fill the yellow columns: pick "Your decision" from the list, add anything else in "Remarks".
A12: TTSPL | B12: Serial id | C12: Serial no | D12: Status | E12: Customer | F12: Current DC | G12: Monthly rate (Rs) | H12: Rent start | I12: Billed until | J12: Problem | K12: What to check for this row | L12: Your decision | M12: Remarks
B13: 8285 | C13: CN-05NT8R-PRC00-39K-06KG | D13: rented | E13: SUKHMAA SONS AND ASSOCIATES | G13: 1 | H13: 2026-07-17 | I13: 2026-09-30 | J13: no TTSPL code | K13: Missing: no TTSPL code. Give the correct value in Remarks, or confirm laptop is not with customer.
B14: 8286 | C14: CN-05NT8R-PRC00-39K-06KF | D14: rented | E14: SUKHMAA SONS AND ASSOCIATES | G14: 1 | H14: 2026-07-17 | I14: 2026-09-30 | J14: no TTSPL code | K14: Missing: no TTSPL code. Give the correct value in Remarks, or confirm laptop is not with customer.
B15: 3749 | C15: PG02Y0BH | D15: rented | E15: NOTUS SERVICES PRIVATE LIMITED | F15: DC-003631 | G15: 1800 | H15: 2026-06-22 | I15: 2026-09-30 | J15: no TTSPL code | K15: Missing: no TTSPL code. Give the correct value in Remarks, or confirm laptop is not with customer.
A16: TTSPLGR0127 | B16: 439 | C16: J2WN8S2 | D16: rented | E16: PARTS AVATAR INDIA PRIVATE LIMITED | G16: 1250 | J16: no rent start date | K16: Missing: no rent start date. Give the correct value in Remarks, or confirm laptop is not with customer.
A17: TTSPL1973 | B17: 2031 | C17: C4TDTQ2 | D17: rented | E17: PARTS AVATAR INDIA PRIVATE LIMITED | G17: 1250 | J17: no rent start date | K17: Missing: no rent start date. Give the correct value in Remarks, or confirm laptop is not with customer.
B18: 2789 | C18: 10W7103 | D18: rented | E18: PARTS AVATAR INDIA PRIVATE LIMITED | F18: DC-000744 | G18: 1250 | H18: 2026-02-06 | I18: 2026-08-31 | J18: no TTSPL code | K18: Missing: no TTSPL code. Give the correct value in Remarks, or confirm laptop is not with customer.
B19: 2513 | C19: 32PXVM3. | D19: returned | E19: FLEET LABS TECHNOLOGIES PRIVATE LIMITED | F19: DC-001997 | G19: 2069.23 | H19: 2026-02-06 | I19: 2026-07-17 | J19: no TTSPL code | K19: Missing: no TTSPL code. Give the correct value in Remarks, or confirm laptop is not with customer.
A20: TTSPL1942 | B20: 2246 | C20: C02G84DNQ6L4 | D20: rented | E20: ANTINO LABS PRIVATE LIMITED | F20: DC-000528 | G20: 0 | H20: 2026-02-06 | I20: 2026-09-30 | J20: no rate | K20: Missing: no rate. Give the correct value in Remarks, or confirm laptop is not with customer.
B21: 3769 | C21: 5GLZP13. | D21: returned | E21: Clanify Media Private Limited | F21: DC-003834 | G21: 0 | H21: 2026-04-29 | I21: 2026-07-17 | J21: no rate, no TTSPL code | K21: Missing: no rate, no TTSPL code. Give the correct value in Remarks, or confirm laptop is not with customer.
B22: 3949 | C22: PC1X7G4H | D22: returned | E22: BRAINBOX NETWORK | F22: DC/26-27/0395 | G22: 620.97 | H22: 2026-05-19 | I22: 2026-07-17 | J22: no TTSPL code | K22: Missing: no TTSPL code. Give the correct value in Remarks, or confirm laptop is not with customer.
B23: 8284 | C23: CN-0657PN-64180-548-046B | D23: rented | E23: BRAINBOX NETWORK | G23: 1 | H23: 2026-07-17 | I23: 2026-09-30 | J23: no TTSPL code | K23: Missing: no TTSPL code. Give the correct value in Remarks, or confirm laptop is not with customer.
A24: TTSPL3537 | B24: 850 | C24: PC1M8NXD | D24: rented | E24: TRUETECH SERVICES PRIVATE LIMITED | G24: 1 | J24: no rent start date | K24: Missing: no rent start date. Give the correct value in Remarks, or confirm laptop is not with customer.
B25: 1551 | C25: PC28HQ2R-erp1551 | D25: returned | E25: EXOTALENT CONSULTANCY SERVICES LLP | F25: DC-003761 | G25: 119.93 | H25: 2026-04-27 | I25: 2026-07-17 | J25: no TTSPL code | K25: Missing: no TTSPL code. Give the correct value in Remarks, or confirm laptop is not with customer.
B26: 3770 | C26: CSSS103. | D26: returned | E26: CARRUM MOBILITY SOLUTIONS PRIVATE LIMITED(HR) | F26: DC-003835 | G26: 3321.43 | H26: 2026-02-26 | I26: 2026-07-17 | J26: no TTSPL code | K26: Missing: no TTSPL code. Give the correct value in Remarks, or confirm laptop is not with customer.
A27: TTSPL5286 | B27: 10929 | C27: PF255KE1 | D27: rented | E27: TechIt Digital | F27: SDC/26-27/0011 | G27: 0 | J27: no rate, no rent start date | K27: Missing: no rate, no rent start date. Give the correct value in Remarks, or confirm laptop is not with customer.
A28: TTSPL6107 | B28: 3236 | C28: PF31SJN6 | D28: rented | E28: PRO-ALIGN SECURITY INDIA PRIVATE LIMITED | J28: no rate, no rent start date | K28: Missing: no rate, no rent start date. Give the correct value in Remarks, or confirm laptop is not with customer.

Sheet 7 In transit
A1: Case 7 — Laptops dispatched 26–30 Sep, not yet delivered
A3: What this is | B3: These laptops left the warehouse at the end of September. The run will start their billing on 1 Oct: the September days (dispatch to 30 Sep) are dropped, and the courier rule (rent from delivery or dispatch + 3 days, whichever is earlier) is not applied — October is billed from 1 Oct even if delivery is later.
A5: How to verify (step by step) | B5: 1. Check the courier/porter status: actual delivery date of each laptop. 2. For in-house delivery (TTSPL7206): rent starts on dispatch day (30 Sep) — 1 day of September. 3. For courier: rent starts on delivery or dispatch + 3 days, whichever is earlier — usually 1–3 Oct. 4. Decide if the small difference (0–4 days each) is acceptable this month.
A7: Recommendation | B7: Accept this month (difference is a few days per laptop); correct any laptop that is not delivered by 3–4 Oct.
A11: Fill the yellow columns: pick "Your decision" from the list, add anything else in "Remarks".
A12: TTSPL | B12: Customer | C12: DC | D12: Mode | E12: Dispatched | F12: Rent start (system) | G12: Billed until | H12: Monthly rate (Rs) | I12: What to check for this row | J12: Your decision | K12: Remarks
A13: TTSPL4895 | B13: Upila Digital | C13: DC/26-27/1397 | D13: courier | E13: 2026-09-26 | F13: 2026-09-26 | H13: 8500 | I13: Courier dispatched 2026-09-26: rent should start at delivery or dispatch+3. Note actual delivery date.
A14: TTSPL6324 | B14: NEURA DYNAMICS PRIVATE LIMITED | C14: DC/26-27/1413 | D14: courier | E14: 2026-09-28 | F14: 2026-09-28 | G14: 2026-09-30 | H14: 3699 | I14: Courier dispatched 2026-09-28: rent should start at delivery or dispatch+3. Note actual delivery date.
A15: TTSPL3676 | B15: RHOPHI ANALYTICS LLP (Punjab) | C15: DC/26-27/1414 | D15: courier | E15: 2026-09-28 | F15: 2026-09-28 | H15: 5499 | I15: Courier dispatched 2026-09-28: rent should start at delivery or dispatch+3. Note actual delivery date.
A16: TTSPL4792 | B16: FLEET LABS TECHNOLOGIES PRIVATE LIMITED | C16: DC/26-27/1421 | D16: courier | E16: 2026-09-29 | F16: 2026-09-29 | H16: 2699 | I16: Courier dispatched 2026-09-29: rent should start at delivery or dispatch+3. Note actual delivery date.
A17: TTSPL2182 | B17: SPNN BUSINESS SERVICES PRIVATE LIMITED | C17: DC/26-27/1423 | D17: courier | E17: 2026-09-29 | F17: 2026-09-29 | H17: 1699 | I17: Courier dispatched 2026-09-29: rent should start at delivery or dispatch+3. Note actual delivery date.
A18: TTSPL6314 | B18: FLEET LABS TECHNOLOGIES PRIVATE LIMITED | C18: DC/26-27/1431 | D18: courier | E18: 2026-09-30 | F18: 2026-09-30 | H18: 2699 | I18: Courier dispatched 2026-09-30: rent should start at delivery or dispatch+3. Note actual delivery date.
A19: TTSPL6213 | B19: FLEET LABS TECHNOLOGIES PRIVATE LIMITED | C19: DC/26-27/1430 | D19: courier | E19: 2026-09-30 | F19: 2026-09-30 | H19: 2199 | I19: Courier dispatched 2026-09-30: rent should start at delivery or dispatch+3. Note actual delivery date.
A20: TTSPL7206 | B20: RASAYANAM NUTRIPHARM PRIVATE LIMITED | C20: DC/26-27/1432 | D20: inhouse | E20: 2026-09-30 | F20: 2026-09-30 | H20: 1999 | I20: In-house: rent from 30 Sep (1 Sept day dropped).
A21: TTSPL3750 | B21: NOTUS SERVICES PRIVATE LIMITED | C21: DC/26-27/1434 | D21: courier | E21: 2026-09-30 | F21: 2026-09-30 | H21: 1700 | I21: Courier dispatched 2026-09-30: rent should start at delivery or dispatch+3. Note actual delivery date.
A22: TTSPL3129 | B22: SPNN BUSINESS SERVICES PRIVATE LIMITED | C22: DC/26-27/1435 | D22: courier | E22: 2026-09-30 | F22: 2026-09-30 | H22: 1700 | I22: Courier dispatched 2026-09-30: rent should start at delivery or dispatch+3. Note actual delivery date.
A23: TTSPL7162 | B23: Optimizing Resources Private Limited | C23: DC/26-27/1437 | D23: courier | E23: 2026-09-30 | F23: 2026-09-30 | H23: 1600 | I23: Courier dispatched 2026-09-30: rent should start at delivery or dispatch+3. Note actual delivery date.
A24: TTSPL3138 | B24: SPNN BUSINESS SERVICES PRIVATE LIMITED | C24: DC/26-27/1439 | D24: courier | E24: 2026-09-30 | F24: 2026-09-30 | H24: 1700 | I24: Courier dispatched 2026-09-30: rent should start at delivery or dispatch+3. Note actual delivery date.
A25: TTSPL7758 | B25: NUTRITIONALAB PRIVATE LIMITED | C25: DC/26-27/1438 | D25: courier | E25: 2026-09-30 | F25: 2026-09-30 | H25: 1999 | I25: Courier dispatched 2026-09-30: rent should start at delivery or dispatch+3. Note actual delivery date.
A26: TTSPL7767 | B26: NUTRITIONALAB PRIVATE LIMITED | C26: DC/26-27/1438 | D26: courier | E26: 2026-09-30 | F26: 2026-09-30 | H26: 1999 | I26: Courier dispatched 2026-09-30: rent should start at delivery or dispatch+3. Note actual delivery date.
... A28: TTSPL7778 | B28: NUTRITIONALAB PRIVATE LIMITED | C28: DC/26-27/1438 | D28: courier | E28: 2026-09-30 | F28: 2026-09-30 | H28: 1999 | I28: Courier dispatched 2026-09-30: rent should start at delivery or dispatch+3. Note actual delivery date.

Sheet 8 Demo & Rs1
A1: Case 8 — Laptops on DEMO orders or at Rs 1 / Rs 0 rate
A3: What this is | B3: These laptops are with customers on demo orders or at a Rs 1 (or less) monthly rate. The run will create Rs 1-type invoice lines for them. TTSPL7002 (Nutritionalab) is on a DEMO order but priced Rs 2,899. TTSPL3589 (Truetech) is billed Rs 1 although its order says Rs 1,000. Truetech (customer 163) has 12 such laptops.
A5: How to verify (step by step) | B5: 1. Confirm with sales whether each demo is still free, or has converted to a paid rental (then give the rate). 2. TTSPL7002: demo (free) or paid rental at Rs 2,899? 3. TTSPL3589: should it be Rs 1,000 as per the order? 4. Rows with a blank customer are old records not linked to anyone — they will not be billed. 5. TTSPL3059 appears here too — it is handled in case 5.
A7: Recommendation | B7: Tell me per row: keep free (exclude), or give the paid rate.
A11: Fill the yellow columns: pick "Your decision" from the list, add anything else in "Remarks".
A12: TTSPL | B12: Status | C12: Customer | D12: Current DC | E12: Sales order | F12: Order type | G12: Order rate (Rs) | H12: Billed rate (Rs) | I12: Billed until | J12: What to check for this row | K12: Your decision | L12: Remarks
A13: TTSPL7002 | B13: rented | C13: NUTRITIONALAB PRIVATE LIMITED | D13: DC/26-27/1351 | E13: SO/26-27/1367 | F13: demo | G13: 2900 | H13: 2899 | J13: Order rate differs from billed rate — which is right?
A14: TTSPL2993 | B14: rented | C14: SLEEP MANAGEMENT PRIVATE LIMITED | D14: DC-003485 | E14: SO-003565 | F14: rental | G14: 1 | H14: 1 | I14: 2026-09-30 | J14: Demo / Rs 1 laptop — still free, or now a paid rental?
A15: TTSPL3437 | B15: rented | C15: SLEEP MANAGEMENT PRIVATE LIMITED | D15: DC-003484 | E15: SO-003564 | F15: rental | G15: 1 | H15: 1 | I15: 2026-09-30 | J15: Demo / Rs 1 laptop — still free, or now a paid rental?
A16: TTSPL3059 | B16: rented | C16: RRA Project Management Private Limited | D16: DC/26-27/1268 | E16: SO/26-27/1292 | F16: sale | G16: 1 | H16: 20000 | I16: 2026-08-31 | J16: Handled in case 5.
A17: TTSPL3977 | B17: rented | C17: ASCENT RISK & RESILIENCE SOFTWARE PRIVATE LIMITED | D17: DC-000434 | E17: SO-000434 | F17: rental | G17: 1 | H17: 1 | I17: 2026-09-30 | J17: Demo / Rs 1 laptop — still free, or now a paid rental?
B18: returned | C18: Clanify Media Private Limited | D18: DC-003834 | E18: SO-003945 | F18: rental | G18: 1200 | H18: 0 | I18: 2026-07-17 | J18: Order rate differs from billed rate — which is right?
A19: TTSPL1984 | B19: returned | C19: TRUETECH SERVICES PRIVATE LIMITED | D19: DC-001163 | E19: SO-001163 | F19: rental | G19: 1 | H19: 0.77 | I19: 2026-07-17 | J19: Demo / Rs 1 laptop — still free, or now a paid rental?
A20: TTSPL2380 | B20: rented | C20: TRUETECH SERVICES PRIVATE LIMITED | D20: DC-001161 | E20: SO-001161 | F20: rental | G20: 1 | H20: 1 | I20: 2026-08-31 | J20: Demo / Rs 1 laptop — still free, or now a paid rental?
A21: TTSPL3492 | B21: rented | C21: TRUETECH SERVICES PRIVATE LIMITED | D21: DC-003686 | E21: SO-003786 | F21: demo | G21: 1 | H21: 1 | I21: 2026-08-31 | J21: Demo / Rs 1 laptop — still free, or now a paid rental?
A22: TTSPL3589 | B22: rented | C22: TRUETECH SERVICES PRIVATE LIMITED | D22: DC-003145 | E22: SO-003177 | F22: rental | G22: 1000 | H22: 1 | I22: 2026-08-31 | J22: Order rate differs from billed rate — which is right?
A23: TTSPL4169 | B23: rented | C23: TRUETECH SERVICES PRIVATE LIMITED | D23: DC-001169 | E23: SO-001169 | F23: rental | G23: 1 | H23: 1 | I23: 2026-08-31 | J23: Demo / Rs 1 laptop — still free, or now a paid rental?
A24: TTSPL4229 | B24: rented | C24: TRUETECH SERVICES PRIVATE LIMITED | D24: DC-001170 | E24: SO-001170 | F24: rental | G24: 1 | H24: 1 | I24: 2026-08-31 | J24: Demo / Rs 1 laptop — still free, or now a paid rental?
A25: TTSPL5083 | B25: rented | C25: TRUETECH SERVICES PRIVATE LIMITED | D25: DC/26-27/0745 | E25: SO/26-27/0741 | F25: demo | G25: 1 | H25: 1 | I25: 2026-08-31 | J25: Demo / Rs 1 laptop — still free, or now a paid rental?
A26: TTSPL5340 | B26: returned | C26: TRUETECH SERVICES PRIVATE LIMITED | D26: DC/26-27/0407 | E26: SO/26-27/0376 | F26: demo | G26: 1 | H26: 0.35 | I26: 2026-07-17 | J26: Demo / Rs 1 laptop — still free, or now a paid rental?
A27: TTSPL5345 | B27: rented | C27: TRUETECH SERVICES PRIVATE LIMITED | D27: DC-001168 | E27: SO-001168 | F27: rental | G27: 1 | H27: 1 | I27: 2026-08-31 | J27: Demo / Rs 1 laptop — still free, or now a paid rental?
A28: TTSPL5620 | B28: rented | C28: TRUETECH SERVICES PRIVATE LIMITED | D28: DC-001173 | E28: SO-001173 | F28: rental | G28: 1 | H28: 1 | I28: 2026-08-31 | J28: Demo / Rs 1 laptop — still free, or now a paid rental?
A29: TTSPL6260 | B29: rented | C29: TRUETECH SERVICES PRIVATE LIMITED | D29: DC/26-27/0356 | E29: SO/26-27/0319 | F29: rental | G29: 1 | H29: 1 | I29: 2026-08-31 | J29: Demo / Rs 1 laptop — still free, or now a paid rental?
A30: TTSPL7300 | B30: rented | C30: TRUETECH SERVICES PRIVATE LIMITED | D30: DC/26-27/0421 | E30: SO/26-27/0392 | F30: demo | G30: 1 | H30: 1 | I30: 2026-08-31 | J30: Demo / Rs 1 laptop — still free, or now a paid rental?
... A33: TTSPL6663 | B33: returned | C33: SPNN BUSINESS SERVICES PRIVATE LIMITED | D33: DC-003400 | E33: SO-003461 | F33: demo | G33: 1 | H33: 0.23 | I33: 2026-07-17 | J33: Demo / Rs 1 laptop — still free, or now a paid rental?
A34: TTSPL1420 | B34: returned | D34: DC-003826 | E34: SO-003932 | F34: rental | G34: 999 | H34: 0 | I34: 2026-06-30 | J34: Not linked to a customer — not billed.
A35: TTSPL1479 | B35: returned | D35: DC-003656 | E35: SO-003752 | F35: sale | G35: 8474 | J35: Not linked to a customer — not billed.
A36: TTSPL1803 | B36: returned | D36: DC-003562 | E36: SO-003645 | F36: sale | G36: 13593 | J36: Not linked to a customer — not billed.
A37: TTSPL4124 | B37: returned | D37: DC-003319 | E37: SO-003374 | F37: rental | G37: 1 | H37: 0.55 | I37: 2026-06-30 | J37: Not linked to a customer — not billed.

Sheet 9 Linked not billed
A1: Case 9 — Laptops linked to a customer but in a status that is never billed
A3: What this is | B3: The run only bills laptops that are "rented", "returned" or "in transit". These laptops still point to a customer but are on demo, in stock, scrapped, reserved or in repair, so they will not be billed.
A5: How to verify (step by step) | B5: 1. on_demo: confirm the demo is free (then nothing to bill). 2. in_stock / scrapped: confirm the laptop is really in our warehouse / scrapped — the customer link is left over. 3. reserved: laptops attached to a new order, not dispatched yet — nothing to bill (normal). 4. in_repair (TTSPL3950): confirm whether it is at the customer or with us.
A7: Recommendation | B7: Normally correct to exclude. Flag any laptop that is actually with the customer and should be billed.
A11: Fill the yellow columns: pick "Your decision" from the list, add anything else in "Remarks".
A12: TTSPL / serial id | B12: Status | C12: Customer | D12: Current DC | E12: Monthly rate (Rs) | F12: Billed until | G12: Status changed | H12: What to check for this row | I12: Your decision | J12: Remarks
A13: TTSPL3950 | B13: in_repair | C13: Synergie Network Engineering India Pvt Ltd | D13: VRDC/26-27/0012 | E13: 1532.57 | F13: 2026-07-17 | G13: 2026-08-13 | H13: In repair — at customer or with us?
A14: 6887 | B14: in_stock | C14: SLEEP MANAGEMENT PRIVATE LIMITED | E14: 1999 | G14: 2026-07-17 | H14: In stock but still linked to customer — confirm it is with us.
A15: 4042 | B15: in_stock | C15: SLEEP MANAGEMENT PRIVATE LIMITED | E15: 1999 | G15: 2026-07-17 | H15: In stock but still linked to customer — confirm it is with us.
A16: TTSPL5456 | B16: in_stock | C16: WSB PROJECTS PRIVATE LIMITED | D16: DC-002207 | E16: 1150 | F16: 2026-06-30 | G16: 2026-07-17 | H16: In stock but still linked to customer — confirm it is with us.
A17: TTSPL2111 | B17: in_stock | C17: BLUEJAY WORKTECH PRIVATE LIMITED | D17: DC/26-27/0781 | E17: 995.9 | F17: 2026-06-30 | G17: 2026-07-17 | H17: In stock but still linked to customer — confirm it is with us.
A18: TTSPL7124 | B18: in_stock | C18: Dotnova Aitech Private Limited | D18: DC/26-27/0759 | E18: 299.8 | F18: 2026-06-30 | G18: 2026-07-17 | H18: In stock but still linked to customer — confirm it is with us.
A19: TTSPL2663 | B19: on_demo | C19: TRUETECH SERVICES PRIVATE LIMITED | D19: DC/26-27/1355 | E19: 1 | G19: 2026-09-21 | H19: Demo — confirm it is free.
A20: TTSPL4079 | B20: on_demo | C20: TRUETECH SERVICES PRIVATE LIMITED | D20: DC/26-27/0888 | E20: 1 | G20: 2026-09-26 | H20: Demo — confirm it is free.
A21: TTSPL3597 | B21: on_demo | C21: TRUETECH SERVICES PRIVATE LIMITED | D21: DC/26-27/0926 | E21: 1 | G21: 2026-08-03 | H21: Demo — confirm it is free.
A22: TTSPL1034 | B22: on_demo | C22: TRUETECH SERVICES PRIVATE LIMITED | D22: DC/26-27/1077 | E22: 1 | G22: 2026-08-06 | H22: Demo — confirm it is free.
A23: TTSPL7034 | B23: on_demo | C23: TRUETECH SERVICES PRIVATE LIMITED | D23: DC/26-27/1099 | E23: 1 | F23: 2026-08-31 | G23: 2026-08-10 | H23: Demo — confirm it is free.
A24: TTSPL7598 | B24: on_demo | C24: TRUETECH SERVICES PRIVATE LIMITED | D24: DC/26-27/1385 | E24: 1 | G24: 2026-09-24 | H24: Demo — confirm it is free.
A25: TTSPL6911 | B25: on_demo | C25: TRUETECH SERVICES PRIVATE LIMITED | D25: DC/26-27/1293 | E25: 1 | F25: 2026-08-31 | G25: 2026-09-09 | H25: Demo — confirm it is free.
A26: TTSPL4220 | B26: on_demo | C26: TRUETECH SERVICES PRIVATE LIMITED | D26: DC/26-27/1126 | E26: 1 | G26: 2026-08-13 | H26: Demo — confirm it is free.
A27: TTSPL6988 | B27: on_demo | C27: TRUETECH SERVICES PRIVATE LIMITED | D27: DC/26-27/0767 | E27: 1 | G27: 2026-07-07 | H27: Demo — confirm it is free.
A28: TTSPL4745 | B28: on_demo | C28: TRUETECH SERVICES PRIVATE LIMITED | D28: DC/26-27/1057 | E28: 1 | G28: 2026-08-03 | H28: Demo — confirm it is free.
A29: TTSPL4530 | B29: on_demo | C29: BM Computers | D29: DC-003612 | G29: 2026-07-09 | H29: Demo — confirm it is free.
A30: TTSPL7779 | B30: reserved | C30: QUREX HEALTH PRIVATE LIMITED | G30: 2026-09-30 | H30: Reserved for a new order — normal, not dispatched.
A31: TTSPL7769 | B31: reserved | C31: QUREX HEALTH PRIVATE LIMITED | G31: 2026-09-30 | H31: Reserved for a new order — normal, not dispatched.
A32: TTSPL7780 | B32: reserved | C32: QUREX HEALTH PRIVATE LIMITED | G32: 2026-09-30 | H32: Reserved for a new order — normal, not dispatched.
A33: TTSPL7776 | B33: reserved | C33: QUREX HEALTH PRIVATE LIMITED | G33: 2026-09-30 | H33: Reserved for a new order — normal, not dispatched.
A34: TTSPL7782 | B34: reserved | C34: QUREX HEALTH PRIVATE LIMITED | G34: 2026-09-30 | H34: Reserved for a new order — normal, not dispatched.
A35: TTSPL7547 | B35: reserved | C35: Khelo Tech and Strategy Pvt Ltd | D35: SDC/26-27/0003 | E35: 2599 | F35: 2026-08-31 | G35: 2026-08-20 | H35: Reserved for a new order — normal, not dispatched.
A36: TTSPL2236 | B36: scrapped | C36: Digital Eco Innovision Private Limited | D36: DC-000463 | E36: 1909 | F36: 2026-06-30 | G36: 2026-07-25 | H36: Scrapped but still linked to customer — confirm.
A37: TTSPL5176 | B37: scrapped | C37: Optimizing Resources Private Limited | D37: DC-002236 | E37: 1302.57 | F37: 2026-06-30 | G37: 2026-07-24 | H37: Scrapped but still linked to customer — confirm.
A38: TTSPL4639 | B38: scrapped | C38: FLEET LABS TECHNOLOGIES PRIVATE LIMITED | D38: DC-001922 | E38: 2069.23 | F38: 2026-06-30 | G38: 2026-07-25 | H38: Scrapped but still linked to customer — confirm.
A39: TTSPL6189 | B39: scrapped | C39: Easy Fix Handy Solutions India Private Limited | D39: DC-002452 | E39: 1073.33 | F39: 2026-06-30 | G39: 2026-07-25 | H39: Scrapped but still linked to customer — confirm.
A40: TTSPL4460 | B40: scrapped | C40: Stylework Innovation Hub Pvt Ltd. | D40: DC/26-27/0397 | E40: 490.06 | F40: 2026-06-30 | G40: 2026-07-25 | H40: Scrapped but still linked to customer — confirm.

Sheet 10 Rate differences
A1: Case 10 — Billed rate differs from the sales-order rate
A3: What this is | B3: The invoice uses the laptop's stored (billed) rate. On 27 Sep you confirmed most of these stored rates are right (replacements / renegotiated prices). Still open from that review: TTSPL3246 (Rs 984 vs Rs 15,254), TTSPL3589 (Rs 1), TTSPL3208 (a part-month amount saved as the monthly rate). Rows in red are the open ones.
A5: How to verify (step by step) | B5: 1. Compare "Billed rate" with the customer's agreed monthly price. 2. For red rows confirm the correct monthly rate and write it in Remarks. 3. Other rows were reviewed on 27 Sep — only flag them if something changed.
A7: Recommendation | B7: Keep reviewed rows; give the correct rate for the red rows.
A11: Fill the yellow columns: pick "Your decision" from the list, add anything else in "Remarks".
A12: TTSPL | B12: Customer | C12: Current DC | D12: Sales order | E12: Order rate (Rs) | F12: Billed rate (Rs) | G12: Billed until | H12: What to check for this row | I12: Your decision | J12: Remarks
A13: TTSPL4801 | B13: XSKY LOUNGE HOSPITALITY PRIVATE LIMITED | C13: DC-000068 | D13: SO-000068 | E13: 2899 | F13: 2222.57 | G13: 2026-09-30 | H13: Reviewed 27 Sep (billed rate kept). Flag only if changed.
A14: TTSPL5238 | B14: IIOT INNOVATION PRIVATE LIMITED | C14: DC-003342 | D14: SO-003399 | E14: 2374 | F14: 1999 | G14: 2026-09-30 | H14: Reviewed 27 Sep (billed rate kept). Flag only if changed.
A15: TTSPL4434 | B15: URBANLOGIX GLOBAL INDIA PRIVATE LIMITED | C15: DC/26-27/1009 | D15: SO/26-27/1032 | E15: 1799 | F15: 999 | G15: 2026-09-30 | H15: Reviewed 27 Sep (billed rate kept). Flag only if changed.
A16: TTSPL3208 | B16: Research Nester Private Limited | C16: DC-001363 | D16: SO-001363 | E16: 899 | F16: 689.23 | G16: 2026-07-17 | H16: OPEN from 27 Sep review — confirm the right monthly rate.
A17: TTSPL5523 | B17: LEEWAYHERTZ TECHNOLOGIES PRIVATE LIMITED | C17: DC-001521 | D17: SO-001521 | E17: 4999 | F17: 3999 | G17: 2026-09-30 | H17: Reviewed 27 Sep (billed rate kept). Flag only if changed.
A18: TTSPL3894 | B18: QUEST SOLUTIONS PRIVATE LIMITED | C18: DC-001546 | D18: SO-001546 | E18: 1449 | F18: 1299 | G18: 2026-09-30 | H18: Reviewed 27 Sep (billed rate kept). Flag only if changed.
A19: TTSPL3949 | B19: Synergie Network Engineering India Pvt Ltd | C19: DC-001608 | D19: SO-001608 | E19: 1999 | F19: 1532.57 | G19: 2026-07-17 | H19: Reviewed 27 Sep (billed rate kept). Flag only if changed.
A20: TTSPL3163 | B20: SPNN BUSINESS SERVICES PRIVATE LIMITED | C20: DC-003853 | D20: SO-003963 | E20: 1900 | F20: 1550 | G20: 2026-09-30 | H20: Reviewed 27 Sep (billed rate kept). Flag only if changed.
A21: TTSPL4265 | B21: FLEET LABS TECHNOLOGIES PRIVATE LIMITED | C21: DC-001797 | D21: SO-001797 | E21: 2699 | F21: 2999 | G21: 2026-09-30 | H21: Reviewed 27 Sep (billed rate kept). Flag only if changed.
B22: EXOTALENT CONSULTANCY SERVICES LLP | C22: DC-003761 | D22: SO-003866 | E22: 1799 | F22: 119.93 | G22: 2026-07-17 | H22: Reviewed 27 Sep (billed rate kept). Flag only if changed.
A23: TTSPL5399 | B23: WICK AUTOMATION LLP | C23: DC-003287 | D23: SO-003341 | E23: 1999 | F23: 1599 | G23: 2026-09-30 | H23: Reviewed 27 Sep (billed rate kept). Flag only if changed.
B24: FLEET LABS TECHNOLOGIES PRIVATE LIMITED | C24: DC-001997 | D24: SO-001997 | E24: 2699 | F24: 2069.23 | G24: 2026-07-17 | H24: Reviewed 27 Sep (billed rate kept). Flag only if changed.
A25: TTSPL6605 | B25: CARRUM MOBILITY SOLUTIONS PRIVATE LIMITED(MH) | C25: DC-002950 | D25: SO-002957 | E25: 1999 | F25: 1500 | G25: 2026-09-30 | H25: Reviewed 27 Sep (billed rate kept). Flag only if changed.
A26: TTSPL6626 | B26: CARRUM MOBILITY SOLUTIONS PRIVATE LIMITED(MH) | C26: DC-002950 | D26: SO-002957 | E26: 1999 | F26: 1500 | G26: 2026-09-30 | H26: Reviewed 27 Sep (billed rate kept). Flag only if changed.
A27: TTSPL6633 | B27: CARRUM MOBILITY SOLUTIONS PRIVATE LIMITED(MH) | C27: DC-002950 | D27: SO-002957 | E27: 1999 | F27: 1500 | G27: 2026-09-30 | H27: Reviewed 27 Sep (billed rate kept). Flag only if changed.
A28: TTSPL1538 | B28: ICHELON CONSULTING GROUP | C28: DC-000855 | D28: SO-000855 | E28: 4999 | F28: 3832.57 | G28: 2026-07-17 | H28: Reviewed 27 Sep (billed rate kept). Flag only if changed.
A29: TTSPL3589 | B29: TRUETECH SERVICES PRIVATE LIMITED | C29: DC-003145 | D29: SO-003177 | E29: 1000 | F29: 1 | G29: 2026-08-31 | H29: OPEN from 27 Sep review — confirm the right monthly rate.
A30: TTSPL3201 | B30: SPNN BUSINESS SERVICES PRIVATE LIMITED | C30: DC-003853 | D30: SO-003963 | E30: 1900 | F30: 1550 | G30: 2026-09-30 | H30: Reviewed 27 Sep (billed rate kept). Flag only if changed.
A31: TTSPL6899 | B31: EXIMPLE TECHNOLOGIES PRIVATE LIMITED | C31: DC-002998 | D31: SO-003011 | E31: 1499 | F31: 1449 | G31: 2026-09-30 | H31: Reviewed 27 Sep (billed rate kept). Flag only if changed.
A32: TTSPL6187 | B32: Digital Eco Innovision Private Limited | C32: DC-003093 | D32: SO-003123 | E32: 2499 | F32: 267.75 | G32: 2026-07-17 | H32: Reviewed 27 Sep (billed rate kept). Flag only if changed.
A33: TTSPL6483 | B33: EXIMPLE TECHNOLOGIES PRIVATE LIMITED | C33: DC-003140 | D33: SO-003172 | E33: 1499 | F33: 1449 | G33: 2026-09-30 | H33: Reviewed 27 Sep (billed rate kept). Flag only if changed.
A34: TTSPL6999 | B34: ASL GLOBAL ADVISORS PRIVATE LIMITED | C34: DC-003168 | D34: SO-003206 | E34: 1000 | F34: 2399 | G34: 2026-09-30 | H34: Reviewed 27 Sep (billed rate kept). Flag only if changed.
