Workbook

Sheet Summary
A1: Billing run 1 Oct 2026 — final check (questions before generating)
A2: Built 30 Sep 2026 night from the live CRM plus a full rolled-back simulation of the October run (207 customers, 0 errors, nothing saved).
A4: Customers in the run | C4: 207
A5: October invoices that would be created | C5: 199
A6: Laptops rented/in transit on a customer | C6: 3086
A7: …of which on an October invoice | C7: 3080
A8: Not on an invoice (see Q7) | C8: 6
A9: Invoice subtotals before GST, rent + security (Rs) | C9: ='October preview'!J212 -> 7972997.2
A10: Return credit notes the run creates (Rs) | C10: 96606.46 | D10: Sum of tab "Info - no answer needed", block C
A12: Q | B12: Tab | C12: Question | D12: Rows | E12: Amount (Rs) | F12: Answered | G12: Blocks the run?
A13: Q1 | B13: Q1 PPG postpaid | C13: PPG August invoice INV-0974 would be overwritten | D13: =COUNTA('Q1 PPG postpaid'!A7:A8) -> 2 | E13: - | F13: =COUNTA('Q1 PPG postpaid'!I7:I8)&" of "&COUNTA('Q1 PPG postpaid'!A7:A8) -> 2 of 2 | G13: Yes
A14: Q2 | B14: Q2 TTSPL3059 | C14: TTSPL3059 sold laptop would be billed Rs 38,000 | D14: =COUNTA('Q2 TTSPL3059'!A7) -> 1 | E14: =SUM('Q2 TTSPL3059'!I7) -> 38000 | F14: =COUNTA('Q2 TTSPL3059'!J7)&" of "&COUNTA('Q2 TTSPL3059'!A7) -> 1 of 1 | G14: Yes
A15: Q3 | B15: Q3 Credits kept | C15: 36 credit lines: keep credit, restore Sept invoice line to full month | D15: =COUNTA('Q3 Credits kept'!A7:A42) -> 36 | E15: =SUM('Q3 Credits kept'!J7:J42) -> 73198.64 | F15: =COUNTA('Q3 Credits kept'!K7:K42)&" of "&COUNTA('Q3 Credits kept'!A7:A42) -> 36 of 36 | G15: Yes
A16: Q4 | B16: Q4 Credits cancel | C16: 6 credit notes to cancel (repair-window + June) | D16: =COUNTA('Q4 Credits cancel'!A7:A12) -> 6 | E16: =SUM('Q4 Credits cancel'!F7:F12) -> 854.54 | F16: =COUNTA('Q4 Credits cancel'!H7:H12)&" of "&COUNTA('Q4 Credits cancel'!A7:A12) -> 6 of 6 | G16: Yes
A17: Q5 | B17: Q5 TTSPL3450 | C17: TTSPL3450 Ratham may be owed Rs 1,380 credit | D17: =COUNTA('Q5 TTSPL3450'!A7) -> 1 | E17: =SUM('Q5 TTSPL3450'!G7) -> 1380 | F17: =COUNTA('Q5 TTSPL3450'!H7)&" of "&COUNTA('Q5 TTSPL3450'!A7) -> 0 of 1 | G17: No
A18: Q6 | B18: Q6 Credit over bill | C18: 3 customers: credit larger than the October bill | D18: =COUNTA('Q6 Credit over bill'!A7:A9) -> 3 | E18: =SUM('Q6 Credit over bill'!E7:E9) -> 3923.8 | F18: =COUNTA('Q6 Credit over bill'!F7:F9)&" of "&COUNTA('Q6 Credit over bill'!A7:A9) -> 0 of 3 | G18: No
A19: Q7 | B19: Q7 Not billed | C19: 6 rented laptops skipped (no rate / no start date) | D19: =COUNTA('Q7 Not billed'!A7:A12) -> 6 | E19: - | F19: =COUNTA('Q7 Not billed'!H7:H12)&" of "&COUNTA('Q7 Not billed'!A7:A12) -> 0 of 6 | G19: No
A20: Q8 | B20: Q8 Rs1 laptops | C20: 25 laptops at Rs 1/month | D20: =COUNTA('Q8 Rs1 laptops'!A7:A31) -> 25 | E20: - | F20: =COUNTA('Q8 Rs1 laptops'!F7:F31)&" of "&COUNTA('Q8 Rs1 laptops'!A7:A31) -> 0 of 25 | G20: No
A21: Q9 | B21: Q9 Rates | C21: 3 laptops: which monthly rate is right | D21: =COUNTA('Q9 Rates'!A7:A9) -> 3 | E21: - | F21: =COUNTA('Q9 Rates'!G7:G9)&" of "&COUNTA('Q9 Rates'!A7:A9) -> 3 of 3 | G21: No
A22: Q10 | B22: Q10 GSTIN | C22: 10 customers without GSTIN | D22: =COUNTA('Q10 GSTIN'!A7:A16) -> 10 | E22: - | F22: =COUNTA('Q10 GSTIN'!F7:F16)&" of "&COUNTA('Q10 GSTIN'!A7:A16) -> 0 of 10 | G22: No
A23: Q11 | B23: Q11 Old repairs | C23: 4 old repairs: going back to the customer or not | D23: =COUNTA('Q11 Old repairs'!A7:A10) -> 4 | E23: - | F23: =COUNTA('Q11 Old repairs'!G7:G10)&" of "&COUNTA('Q11 Old repairs'!A7:A10) -> 4 of 4 | G23: No
A25: How to use: open each Q tab, read the three lines at the top, then fill the yellow "Your answer" (drop-down) and "Remarks" columns. Nothing else needs editing.
A26: Example: tab "Q2 TTSPL3059", row TTSPL3059 → Your answer = "Yes - mark sold", Remarks = "Warranty replacement for TTSPL6191".
A27: "Blocks the run?" = Yes means the run would do something wrong (overwrite or bill/credit money wrongly) if we generate before your answer. The others can be fixed after the run.
A28: After your answers: I apply the fixes (dry run + backup first), repeat this simulation, and only then you click Generate invoices once for October.

Sheet Q1 PPG postpaid
A1: Q1 — PPG Asian Paints (postpaid): August invoice would be overwritten
A2: What this is | B2: PPG is the only postpaid customer. The run bills September occupancy and looks for the existing draft; it finds the August invoice INV-0974 (still draft) and rebuilds it with September lines.
A3: My recommendation | B3: If INV-0052 and INV-0974 were issued to PPG in Zoho, I mark both "sent" before the run. The run then creates a new September invoice and August stays as issued.
A4: Your answer | B4: Issued in Zoho - mark sent / Not issued - leave
A6: Invoice | B6: Month | C6: Status | D6: From | E6: To | F6: Subtotal (Rs) | G6: Grand total (Rs) | H6: What happens | I6: Your answer | J6: Remarks
A7: INV-0052 | B7: 7 | C7: draft | D7: 2026-07-01 | E7: 2026-07-31 | F7: 20985 | G7: 24762.3 | H7: July bill, still draft. Not touched by the run. | I7: Issued in Zoho - mark sent
A8: INV-0974 | B8: 9 | C8: draft | D8: 2026-08-01 | E8: 2026-08-31 | F8: 19676.25 | G8: 23217.97 | H8: August bill. The run would REBUILD this draft with September data (new subtotal 16,974.53) and August would be lost. | I8: Issued in Zoho - mark sent

Sheet Q2 TTSPL3059
A1: Q2 — TTSPL3059: sold laptop still set up as rented at Rs 20,000/month
A2: What this is | B2: TTSPL3059 replaced sold laptop TTSPL6191 for RRA Project Management (warranty) but was put on a new SO/26-27/1292 and left "rented" at the Rs 20,000 sale price. You decided on 27 Sep that a sale replacement goes on the original sale SO at Rs 0.
A3: My recommendation | B3: Before the run I mark TTSPL3059 "sold" on the original sale order SO/25-26/3019 at Rs 0, so it is not billed.
A4: Your answer | B4: Yes - mark sold / No - it is a rental
A6: TTSPL | B6: Customer | C6: Current DC | D6: Sales order | E6: Status | F6: Monthly rate (Rs) | G6: Run would bill Sept (Rs) | H6: Run would bill Oct (Rs) | I6: Total (Rs) | J6: Your answer | K6: Remarks
A7: TTSPL3059 | B7: RRA Project Management Private Limited | C7: DC/26-27/1268 | D7: SO/26-27/1292 | E7: rented | F7: 20000 | G7: 18000 | H7: 20000 | I7: =G7+H7 -> 38000 | J7: Yes - mark sold

Sheet Q3 Credits kept
A1: Q3 — Returned laptops: invoice line was trimmed later, credit note pending
A2: What this is | B2: Same situation as TTSPL7540 and TTSPL5452. Each September invoice was created on 1–2 Sep (before the laptop came back) and later trimmed in the CRM to the return date, while a credit note for the rest of September is pending. If Zoho billed the full month, the credit is correct and the CRM invoice line is wrong.
A3: My recommendation | B3: Keep every credit note. Put the CRM September line back to 1–30 Sep so the CRM matches Zoho (as done for TTSPL4837 / TTSPL4405). If any customer was billed only to the return date in Zoho, write "Cancel credit" on that row.
A4: Your answer | B4: Keep credit - restore line / Cancel credit
A6: Credit note | B6: Customer | C6: TTSPL | D6: Warehouse received | E6: Invoice | F6: Invoice status | G6: Invoice created | H6: Invoice line (CRM now) | I6: Credit period | J6: Credit (Rs) | K6: Your answer | L6: Remarks
A7: CN-0253 | B7: ASCENT RISK & RESILIENCE SOFTWARE PRIVATE LIMITED | C7: TTSPL4752 | D7: 2026-09-07 | E7: INV-1031 | F7: draft | G7: 2026-09-02 | H7: 2026-09-01 to 2026-09-07 | I7: 2026-09-08 to 2026-09-30 | J7: 2683.33 | K7: Keep credit - restore line
A8: CN-0255 | B8: ASCENT RISK & RESILIENCE SOFTWARE PRIVATE LIMITED | C8: TTSPL4940 | D8: 2026-09-09 | E8: INV-1031 | F8: draft | G8: 2026-09-02 | H8: 2026-09-01 to 2026-09-09 | I8: 2026-09-10 to 2026-09-30 | J8: 2449.3 | K8: Keep credit - restore line
A9: CN-0253 | B9: ASCENT RISK & RESILIENCE SOFTWARE PRIVATE LIMITED | C9: TTSPL6511 | D9: 2026-09-08 | E9: INV-1031 | F9: draft | G9: 2026-09-02 | H9: 2026-09-01 to 2026-09-08 | I9: 2026-09-09 to 2026-09-30 | J9: 2565.93 | K9: Keep credit - restore line
A10: CN-0253 | B10: ASCENT RISK & RESILIENCE SOFTWARE PRIVATE LIMITED | C10: TTSPL6959 | D10: 2026-09-08 | E10: INV-1031 | F10: draft | G10: 2026-09-02 | H10: 2026-09-01 to 2026-09-08 | I10: 2026-09-09 to 2026-09-30 | J10: 2566.67 | K10: Keep credit - restore line
A11: CN-0274 | B11: BIODEAL PHARMACEUTICALS LIMITED | C11: TTSPL5496 | D11: 2026-09-17 | E11: INV-1043 | F11: sent | G11: 2026-09-02 | H11: 2026-09-01 to 2026-09-17 | I11: 2026-09-18 to 2026-09-30 | J11: 650 | K11: Keep credit - restore line
A12: CN-0274 | B12: BIODEAL PHARMACEUTICALS LIMITED | C12: TTSPL6630 | D12: 2026-09-19 | E12: INV-1043 | F12: sent | G12: 2026-09-02 | H12: 2026-09-01 to 2026-09-19 | I12: 2026-09-20 to 2026-09-30 | J12: 550 | K12: Keep credit - restore line
A13: CN-0256 | B13: BIODEAL PHARMACEUTICALS LIMITED | C13: TTSPL6827 | D13: 2026-09-07 | E13: INV-1043 | F13: sent | G13: 2026-09-02 | H13: 2026-09-01 to 2026-09-07 | I13: 2026-09-08 to 2026-09-30 | J13: 1150 | K13: Keep credit - restore line
A14: CN-0024 | B14: Beom Commerce Private Limited | C14: TTSPL4943 | D14: 2026-09-02 | E14: INV-1005 | F14: sent | G14: 2026-09-01 | H14: 2026-09-01 to 2026-09-02 | I14: 2026-09-03 to 2026-09-30 | J14: 886.67 | K14: Keep credit - restore line
A15: CN-0263 | B15: DROR SERVICES PRIVATE LIMITED | C15: TTSPL6500 | D15: 2026-09-11 | E15: INV-1065 | F15: draft | G15: 2026-09-02 | H15: 2026-09-01 to 2026-09-11 | I15: 2026-09-12 to 2026-09-30 | J15: 1012.7 | K15: Keep credit - restore line
A16: CN-0248 | B16: FLEET LABS TECHNOLOGIES PRIVATE LIMITED | C16: TTSPL4513 | D16: 2026-09-04 | E16: INV-1081 | F16: draft | G16: 2026-09-02 | H16: 2026-09-01 to 2026-09-04 | I16: 2026-09-05 to 2026-09-30 | J16: 2339.13 | K16: Keep credit - restore line
A17: CN-0264 | B17: FLEET LABS TECHNOLOGIES PRIVATE LIMITED | C17: TTSPL4792 | D17: 2026-09-09 | E17: INV-1081 | F17: draft | G17: 2026-09-02 | H17: 2026-09-01 to 2026-09-09 | I17: 2026-09-10 to 2026-09-30 | J17: 1889.3 | K17: Keep credit - restore line
A18: CN-0248 | B18: FLEET LABS TECHNOLOGIES PRIVATE LIMITED | C18: TTSPL5116 | D18: 2026-09-04 | E18: INV-1081 | F18: draft | G18: 2026-09-02 | H18: 2026-09-01 to 2026-09-04 | I18: 2026-09-05 to 2026-09-30 | J18: 2165.8 | K18: Keep credit - restore line
... A42: CN-0261 | B42: ZENITHIA GARDEN OF JOY PRIVATE LIMITED | C42: TTSPL3186 | D42: 2026-09-15 | E42: INV-1182 | F42: sent | G42: 2026-09-02 | H42: 2026-09-01 to 2026-09-15 | I42: 2026-09-16 to 2026-09-30 | J42: 699.5 | K42: Keep credit - restore line

Sheet Q4 Credits cancel
A1: Q4 — Pending credit notes that go against the agreed rules
A2: What this is | B2: Five "repair window" credit notes credit the days a laptop sat in our warehouse during a repair. Under the rule you confirmed on 30 Sep (repair = continuous rent, no credit), they should not exist. CN-0062 credits one June day that no invoice billed.
A3: My recommendation | B3: Cancel all six before the run.
A4: Your answer | B4: Cancel / Keep
A6: Credit note | B6: Customer | C6: TTSPL | D6: Type | E6: Period | F6: Amount (Rs) | G6: Why | H6: Your answer | I6: Remarks
A7: CN-0062 | B7: BLUEJAY WORKTECH PRIVATE LIMITED | C7: TTSPL2111 | D7: return | E7: 2026-06-30 to 2026-06-30 | F7: 33.2 | G7: Credit for 30 Jun (1 day); no invoice line covers that day. | H7: Cancel | I7: Not required.
A8: CN-0282 | B8: Mercury Solutions Limited | C8: TTSPL3552 | D8: repair | E8: 2026-09-10 to 2026-09-16 | F8: 396.43 | G8: Repair-window credit (warehouse days during a repair). Your 30 Sep rule: repair = continuous rent, no credit. | H8: Keep | I8: I can see that this came back twice in september and again create another DC to send to another location. Check and charge accordingly.
A9: CN-0283 | B9: LEEWAYHERTZ TECHNOLOGIES PRIVATE LIMITED | C9: TTSPL3731 | D9: repair | E9: 2026-09-16 to 2026-09-16 | F9: 94.97 | G9: Repair-window credit (warehouse days during a repair). Your 30 Sep rule: repair = continuous rent, no credit. | H9: Keep | I9: but now, this laptop has been returned. SO, we have to give credit note from warehouse receive date
A10: CN-0284 | B10: LEEWAYHERTZ TECHNOLOGIES PRIVATE LIMITED | C10: TTSPL4019 | D10: repair | E10: 2026-09-24 to 2026-09-24 | F10: 94.97 | G10: Repair-window credit (warehouse days during a repair). Your 30 Sep rule: repair = continuous rent, no credit. | H10: Keep | I10: As this laptop has been sent back in a week only. (So, no credit note)
A11: CN-0285 | B11: RATHAM TECHNOLOGIES LLP | C11: TTSPL4053 | D11: repair | E11: 2026-09-17 to 2026-09-18 | F11: 120 | G11: Repair-window credit (warehouse days during a repair). Your 30 Sep rule: repair = continuous rent, no credit. | H11: Keep | I11: As this laptop has been sent back in a week only. (So, no credit note)
A12: CN-0286 | B12: LEEWAYHERTZ TECHNOLOGIES PRIVATE LIMITED | C12: TTSPL4515 | D12: repair | E12: 2026-09-24 to 2026-09-24 | F12: 114.97 | G12: Repair-window credit (warehouse days during a repair). Your 30 Sep rule: repair = continuous rent, no credit. | H12: Keep | I12: As this laptop has been sent back in a week only. (So, no credit note)

Sheet Q5 TTSPL3450
A1: Q5 — TTSPL3450 (Ratham): trimmed invoice line, no credit note
A2: What this is | B2: The opposite of Q3: INV-1129 was created 2 Sep, the September line for TTSPL3450 was later cut to 1–7 Sep, and no credit note exists. If Zoho billed the full month, Ratham is owed credit for 8–30 Sep.
A3: My recommendation | B3: Same rule as Q3: restore the line to 1–30 Sep and issue a return credit note for 8–30 Sep.
A4: Your answer | B4: Yes - credit / No - Zoho billed only to 7 Sep
A6: TTSPL | B6: Customer | C6: Invoice | D6: Invoice created | E6: Invoice line (CRM now) | F6: Monthly rate (Rs) | G6: Credit 8–30 Sep (Rs) | H6: Your answer | I6: Remarks
A7: TTSPL3450 | B7: RATHAM TECHNOLOGIES LLP | C7: INV-1129 | D7: 2026-09-02 | E7: 2026-09-01 to 2026-09-07 | F7: 1800 | G7: =ROUND(F7*23/30,2) -> 1380

Sheet Q6 Credit over bill
A1: Q6 — Credit notes larger than the October bill
A2: What this is | B2: When a credit note is applied, the invoice cannot go below zero; the extra credit is dropped today (not carried forward).
A3: My recommendation | B3: Apply what fits in October and keep the rest as a pending credit for November (I split the credit note). Or refund it.
A4: Your answer | B4: Carry forward / Refund / Drop
A6: Customer id | B6: Customer | C6: October bill before GST (Rs) | D6: Pending credits (Rs) | E6: Credit that would be lost (Rs) | F6: Your answer | G6: Remarks
A7: 52 | B7: Nexthire LLP | C7: 999 | D7: 3196.8 | E7: =MAX(0,D7-C7) -> 2197.8
A8: 200 | B8: XSKY LOUNGE HOSPITALITY PRIVATE LIMITED | C8: 2899 | D8: 4445.14 | E8: =MAX(0,D8-C8) -> 1546.14
A9: 986 | B9: CARRUM MOBILITY SOLUTIONS PRIVATE LIMITED(KA) | C9: 1500 | D9: 1679.86 | E9: =MAX(0,D9-C9) -> 179.86

Sheet Q7 Not billed
A1: Q7 — Laptops with a customer that the run will NOT bill
A2: What this is | B2: These laptops are rented to a customer but have no monthly rate or no rent start date, so the run skips them silently.
A3: My recommendation | B3: Give me the missing value in Remarks (rate in Rs/month, or start date as YYYY-MM-DD). Write "Free" if it should not be billed.
A4: Your answer | B4: Bill - value in Remarks / Free / Not with customer
A6: TTSPL | B6: Serial | C6: Customer | D6: DC | E6: Monthly rate (Rs) | F6: Rent start | G6: Missing | H6: Your answer | I6: Remarks
A7: TTSPLGR0127 | B7: J2WN8S2 | C7: PARTS AVATAR INDIA PRIVATE LIMITED | E7: 1250 | G7: rent start date
A8: TTSPL3537 | B8: PC1M8NXD | C8: TRUETECH SERVICES PRIVATE LIMITED | E8: 1 | G8: rent start date
A9: TTSPL1973 | B9: C4TDTQ2 | C9: PARTS AVATAR INDIA PRIVATE LIMITED | E9: 1250 | G9: rent start date
A10: TTSPL1942 | B10: C02G84DNQ6L4 | C10: ANTINO LABS PRIVATE LIMITED | D10: DC-000528 | E10: 0 | F10: 2026-02-06 | G10: monthly rate
A11: TTSPL6107 | B11: PF31SJN6 | C11: PRO-ALIGN SECURITY INDIA PRIVATE LIMITED | G11: monthly rate + rent start date
A12: TTSPL5286 | B12: PF255KE1 | C12: TechIt Digital | D12: SDC/26-27/0011 | E12: 0 | G12: monthly rate + rent start date

Sheet Q8 Rs1 laptops
A1: Q8 — Laptops billed at Rs 1 (or less) per month
A2: What this is | B2: These rented laptops will get a Rs 1 line (demo / free units). TruTech and OLA hold most of them.
A3: My recommendation | B3: Confirm each is free. If a laptop should now be paid, put the monthly rate in Remarks.
A4: Your answer | B4: Free - keep Rs 1 / Paid - rate in Remarks
A6: TTSPL | B6: Serial | C6: Customer | D6: DC | E6: Rate (Rs) | F6: Your answer | G6: Remarks
A7: TTSPL3437 | B7: D3Q1F63 | C7: SLEEP MANAGEMENT PRIVATE LIMITED | D7: DC-003484 | E7: 1
A8: TTSPL2993 | B8: 5W5VN73 | C8: SLEEP MANAGEMENT PRIVATE LIMITED | D8: DC-003485 | E8: 1
A9: (no TTSPL) | B9: CN-05NT8R-PRC00-39K-06KF | C9: SUKHMAA SONS AND ASSOCIATES | E9: 1
A10: (no TTSPL) | B10: CN-05NT8R-PRC00-39K-06KG | C10: SUKHMAA SONS AND ASSOCIATES | E10: 1
A11: TTSPL3977 | B11: J4YN8S3 | C11: ASCENT RISK & RESILIENCE SOFTWARE PRIVATE LIMITED | D11: DC-000434 | E11: 1
A12: TTSPL1942 | B12: C02G84DNQ6L4 | C12: ANTINO LABS PRIVATE LIMITED | D12: DC-000528 | E12: 0
A13: (no TTSPL) | B13: CN-0657PN-64180-548-046B | C13: BRAINBOX NETWORK | E13: 1
A14: TTSPL5909 | B14: 5CD1218T2M | C14: OLA | E14: 1
A15: TTSPL5129 | B15: PF55FX53 | C15: OLA | E15: 1
A16: TTSPL5833 | B16: F633JL3 | C16: OLA | E16: 1
A17: TTSPL5603 | B17: PF33C7AF | C17: OLA | E17: 1
A18: TTSPL7300 | B18: 8WZK2J3 | C18: TRUETECH SERVICES PRIVATE LIMITED | D18: DC/26-27/0421 | E18: 1
A19: TTSPL3589 | B19: PC11LLRZ | C19: TRUETECH SERVICES PRIVATE LIMITED | D19: DC-003145 | E19: 1
A20: TTSPL3492 | B20: 85PR3J3 | C20: TRUETECH SERVICES PRIVATE LIMITED | D20: DC-003686 | E20: 1
A21: TTSPL2380 | B21: G1RYBG2 | C21: TRUETECH SERVICES PRIVATE LIMITED | D21: DC-001161 | E21: 1
A22: TTSPL5083 | B22: NO S/N-erp2958 | C22: TRUETECH SERVICES PRIVATE LIMITED | D22: DC/26-27/0745 | E22: 1
A23: TTSPL5345 | B23: 7QDRDK3 | C23: TRUETECH SERVICES PRIVATE LIMITED | D23: DC-001168 | E23: 1
A24: TTSPL4229 | B24: G9J1BC3 | C24: TRUETECH SERVICES PRIVATE LIMITED | D24: DC-001170 | E24: 1
A25: TTSPL6260 | B25: DZ33C63 | C25: TRUETECH SERVICES PRIVATE LIMITED | D25: DC/26-27/0356 | E25: 1
A26: TTSPL5620 | B26: PG02SK9X | C26: TRUETECH SERVICES PRIVATE LIMITED | D26: DC-001173 | E26: 1
A27: TTSPL3537 | B27: PC1M8NXD | C27: TRUETECH SERVICES PRIVATE LIMITED | E27: 1
A28: TTSPL4169 | B28: 6M3Y1F3 | C28: TRUETECH SERVICES PRIVATE LIMITED | D28: DC-001169 | E28: 1
A29: TTSPL5702 | B29: BJQYCL3 | C29: ABJAYON CONSULTANCY PRIVATE LIMITED | D29: DC/26-27/0851 | E29: 1
A30: TTSPL5286 | B30: PF255KE1 | C30: TechIt Digital | D30: SDC/26-27/0011 | E30: 0
A31: TTSPL2863 | B31: GYRXZF2 | C31: Amar Amba Finance Hire Purchase Private Limited | D31: DC-003703 | E31: 1

Sheet Q9 Rates
A1: Q9 — Monthly rate differs from the sales order (open since 27 Sep)
A2: What this is | B2: The billed rate and the sales-order rate disagree. The run bills the billed rate.
A3: My recommendation | B3: Tell me the correct monthly rate in Remarks.
A4: Your answer | B4: Billed rate right / SO rate right / Other - Remarks
A6: TTSPL | B6: Customer | C6: Sales order | D6: SO rate (Rs) | E6: Billed rate (Rs) | F6: Note | G6: Your answer | H6: Remarks
A7: TTSPL3208 | B7: Research Nester Private Limited | C7: SO-001363 | D7: 899 | E7: 689.23 | F7: Run also bills 18 Jul–30 Sep catch-up at 689.23 (Rs 2,379) | G7: Other - Remarks | H7: This should not be billed . Because it is in warehouse. I have checked my master sheet.( return on 3 April 2026)
A8: TTSPL3589 | B8: TRUETECH SERVICES PRIVATE LIMITED | C8: SO-003177 | D8: 1000 | E8: 1 | F8: Billed Rs 1/month | G8: Billed rate right | H8: This is our inhouse billing. Leave as same
A9: TTSPL3246 | B9: BM Computers | C9: SO-003506 | D9: 15254 | E9: 984.13 | F9: SO rate looks like a sale price | G9: SO rate right | H9: This is not rented laptop. This is sales laptop.

Sheet Q10 GSTIN
A1: Q10 — Customers invoiced without a GSTIN
A2: What this is | B2: CGST+SGST or IGST is decided from the GSTIN state (from 30 Sep). Without a GSTIN the billing state is used; Leverage Edu has neither.
A3: My recommendation | B3: Give GSTIN (or confirm B2C / unregistered) in Remarks. Leverage Edu needs at least a billing state.
A4: Your answer | B4: GSTIN in Remarks / Unregistered - use billing state
A6: Customer id | B6: Customer | C6: GSTIN | D6: Billing state | E6: Problem | F6: Your answer | G6: Remarks
A7: 966 | B7: Leverage Edu | E7: No GSTIN and no billing state — tax head defaults to Haryana | G7: I will update tomorrow before generation of invoice
A8: 199 | B8: BIOSKY SPACE INNOVATIONS PRIVATE LIMITED | D8: haryana | E8: No GSTIN | G8: I will update tomorrow before generation of invoice
A9: 200 | B9: XSKY LOUNGE HOSPITALITY PRIVATE LIMITED | D9: haryana | E9: No GSTIN | G9: I will update tomorrow before generation of invoice
A10: 224 | B10: B2C (Pranshu Sharma) | D10: Haryana | E10: No GSTIN | G10: I will update tomorrow before generation of invoice
A11: 259 | B11: CIPHERBEAT LLP | D11: haryana | E11: No GSTIN | G11: I will update tomorrow before generation of invoice
A12: 260 | B12: PRO-ALIGN SECURITY INDIA PRIVATE LIMITED | D12: haryana | E12: No GSTIN | G12: I will update tomorrow before generation of invoice
A13: 265 | B13: 4 PROSPER TECHNOLOGIES PRIVATE LIMITED | D13: Uttar Pradesh | E13: No GSTIN | G13: I will update tomorrow before generation of invoice
A14: 219 | B14: Technians Softech Pvt.Ltd | D14: Haryana | E14: No GSTIN | G14: I will update tomorrow before generation of invoice
A15: 196 | B15: MERVICE INFOTECH PRIVATE LIMITED | D15: Uttar Pradesh | E15: No GSTIN | G15: I will update tomorrow before generation of invoice
A16: 220 | B16: GOOLEAN TECHNOLOGIES PRIVATE LIMITED | D16: Haryana | E16: No GSTIN | G16: I will update tomorrow before generation of invoice

Sheet Q11 Old repairs
A1: Q11 — Repairs from July/August still open, not billed
A2: What this is | B2: Under the repair rule, a laptop going back to the same customer bills continuously. These have been in our warehouse (or at the vendor) since July/August with the ticket still open, and are not billed.
A3: My recommendation | B3: For each: "Going back" = I bill it continuously from pickup; "Not going back" = support closes the ticket and billing stays stopped at warehouse receipt.
A4: Your answer | B4: Going back - bill / Not going back - close
A6: TTSPL | B6: Customer | C6: Ticket | D6: Warehouse received | E6: Rate (Rs) | F6: Note | G6: Your answer | H6: Remarks
A7: TTSPL4856 | B7: Decoreal Aquariums | C7: 2484 | D7: 2026-07-25 | F7: Repair ticket still open (awaiting service return); laptop off customer, not billed since pickup | G7: Not going back - close | H7: CLose the ticket and don't bill for this
A8: TTSPL6901 | B8: BMRV Engineering Consultants LLP | C8: 2677 | D8: 2026-08-05 | E8: 1699 | F8: Repair ticket still open; billed until 31 Aug, not billed since | G8: Not going back - close | H8: CLose the ticket and don't bill for this
A9: TTSPL2454 | B9: QUEST SOLUTIONS PRIVATE LIMITED | C9: 2359 | D9: 2026-07-16 | E9: 2999 | F9: Repair ticket still open; laptop in stock; never billed after pickup | G9: Not going back - close | H9: CLose the ticket and don't bill for this
A10: TTSPL3950 | B10: Synergie Network Engineering India Pvt Ltd | E10: 1532.57 | F10: At vendor on VRDC/26-27/0012 since Jul; still on Synergie (customer 25); billed only to 17 Jul | G10: Not going back - close | H10: CLose the ticket and don't bill for this

Sheet October preview
A1: October 2026 run — simulated on 30 Sep night (nothing saved)
A2: Every customer was run through the real invoice generator inside a transaction that was rolled back. Amounts are before GST; security deposits shown separately.
A4: Customer id | B4: Customer | C4: Type | D4: Invoice | E4: Laptops billed for Oct | F4: October rent (Rs) | G4: September catch-up (Rs) | H4: Older catch-up (Rs) | I4: Security (Rs) | J4: Invoice subtotal (Rs) | K4: Pending credits (Rs)
A5: 48 | B5: PIBIT TECHNOLOGIES PRIVATE LIMITED | C5: prepaid | D5: INV-1196 | E5: 213 | F5: 1004097 | G5: 12436.29 | H5: 0 | I5: 0 | J5: =SUM(F5:I5) -> 1016533.3 | K5: 23631.67
A6: 94 | B6: FLEET LABS TECHNOLOGIES PRIVATE LIMITED | C6: prepaid | D6: INV-1196 | E6: 174 | F6: 454626 | G6: 1122.89 | H6: 0 | I6: 0 | J6: =SUM(F6:I6) -> 455748.89 | K6: 16576.96
A7: 108 | B7: LEEWAYHERTZ TECHNOLOGIES PRIVATE LIMITED | C7: prepaid | D7: INV-1196 | E7: 87 | F7: 342521 | G7: 12619.94 | H7: 0 | I7: 0 | J7: =SUM(F7:I7) -> 355140.94 | K7: 7429.41
A8: 22 | B8: NUTRITIONALAB PRIVATE LIMITED | C8: prepaid | D8: INV-1196 | E8: 64 | F8: 267848 | G8: 22750.95 | H8: 0 | I8: 37394 | J8: =SUM(F8:I8) -> 327992.95 | K8: 1799.53
A9: 106 | B9: RHOPHI ANALYTICS LLP (Punjab) | C9: prepaid | D9: INV-1196 | E9: 50 | F9: 290349 | G9: 31667.3 | H9: 0 | I9: 0 | J9: =SUM(F9:I9) -> 322016.3 | K9: 8348.8
A10: 41 | B10: SLEEP MANAGEMENT PRIVATE LIMITED | C10: prepaid | D10: INV-1196 | E10: 101 | F10: 215409 | G10: 8486.65 | H10: 0 | I10: 0 | J10: =SUM(F10:I10) -> 223895.65 | K10: 1799.1
A11: 29 | B11: Optimizing Resources Private Limited | C11: prepaid | D11: INV-1196 | E11: 120 | F11: 195062 | G11: 10079.99 | H11: 0 | I11: 0 | J11: =SUM(F11:I11) -> 205141.99 | K11: 499.83
A12: 983 | B12: AUGUSTUS & MK CORPORATION PRIVATE LIMITED | C12: prepaid | D12: INV-1196 | E12: 39 | F12: 84972 | G12: 28389.19 | H12: 0 | I12: 76976 | J12: =SUM(F12:I12) -> 190337.19 | K12: 0
A13: 101 | B13: ASCENT RISK & RESILIENCE SOFTWARE PRIVATE LIMITED | C13: prepaid | D13: INV-1196 | E13: 56 | F13: 187285 | G13: 0 | H13: 0 | I13: 0 | J13: =SUM(F13:I13) -> 187285 | K13: 18031.24
A14: 256 | B14: SPNN BUSINESS SERVICES PRIVATE LIMITED | C14: prepaid | D14: INV-1196 | E14: 102 | F14: 171746 | G14: 4923.3 | H14: 0 | I14: 0 | J14: =SUM(F14:I14) -> 176669.3 | K14: 1586.67
A15: 120 | B15: ANTINO LABS PRIVATE LIMITED | C15: prepaid | D15: INV-1196 | E15: 60 | F15: 114942 | G15: 0 | H15: 0 | I15: 0 | J15: =SUM(F15:I15) -> 114942 | K15: 1066.13
A16: 72 | B16: PARTS AVATAR INDIA PRIVATE LIMITED | C16: prepaid | D16: INV-1196 | E16: 41 | F16: 53624 | G16: 53624 | H16: 0 | I16: 0 | J16: =SUM(F16:I16) -> 107248 | K16: 0
... A211: 988 | B211: CARRUM MOBILITY SOLUTIONS PRIVATE LIMITED(DL) | C211: prepaid | D211: (skipped) | E211: 0 | F211: 0 | G211: 0 | H211: 0 | I211: 0 | J211: =SUM(F211:I211) -> 0 | K211: 0
B212: Total | E212: =SUM(E5:E211) -> 3074 | F212: =SUM(F5:F211) -> 7326593.4 | G212: =SUM(G5:G211) -> 429887.89 | H212: =SUM(H5:H211) -> 1222.95 | I212: =SUM(I5:I211) -> 215293 | J212: =SUM(J5:J211) -> 7972997.2 | K212: =SUM(K5:K211) -> 183921.84

Sheet Info - no answer needed
A1: For information — these follow the agreed rules; no answer needed
A3: A. Laptops at the warehouse still billed for October (open repair — rent continues per 30 Sep rule)
A4: TTSPL | B4: Customer | C4: October (Rs)
A5: TTSPL7426 | B5: PIBIT TECHNOLOGIES PRIVATE LIMITED | C5: 4200
A6: TTSPL4626 | B6: LEEWAYHERTZ TECHNOLOGIES PRIVATE LIMITED | C6: 2849
A7: TTSPL1457 | B7: COAL BEAUTY PRIVATE LIMITED | C7: 1199
A8: TTSPL5391 | B8: BIODEAL PHARMACEUTICALS LIMITED | C8: 1500
A9: TTSPL6825 | B9: BIODEAL PHARMACEUTICALS LIMITED | C9: 1500
A10: TTSPL7548 | B10: Khelo Tech and Strategy Pvt Ltd | C10: 2599
A12: B. Dispatched 26–30 Sep, still in transit: billed from 1 Oct (September days not billed, total under Rs 2,000)
A13: TTSPL | B13: Customer | C13: Mode | D13: Dispatched | E13: October (Rs)
A14: TTSPL3676 | B14: RHOPHI ANALYTICS LLP (Punjab) | C14: courier | D14: 2026-09-28 | E14: 5499
A15: TTSPL6324 | B15: NEURA DYNAMICS PRIVATE LIMITED | C15: courier | D15: 2026-09-28 | E15: 3699
A16: TTSPL4792 | B16: FLEET LABS TECHNOLOGIES PRIVATE LIMITED | C16: courier | D16: 2026-09-29 | E16: 2699
A17: TTSPL2182 | B17: SPNN BUSINESS SERVICES PRIVATE LIMITED | C17: courier | D17: 2026-09-29 | E17: 1699
A18: TTSPL4895 | B18: Upila Digital | C18: courier | D18: 2026-09-26 | E18: 8500
A19: TTSPL6314 | B19: FLEET LABS TECHNOLOGIES PRIVATE LIMITED | C19: courier | D19: 2026-09-30 | E19: 2699
A20: TTSPL6213 | B20: FLEET LABS TECHNOLOGIES PRIVATE LIMITED | C20: courier | D20: 2026-09-30 | E20: 2199
A21: TTSPL7206 | B21: RASAYANAM NUTRIPHARM PRIVATE LIMITED | C21: inhouse | D21: 2026-09-30 | E21: 1999
A22: TTSPL3129 | B22: SPNN BUSINESS SERVICES PRIVATE LIMITED | C22: courier | D22: 2026-09-30 | E22: 1700
A23: TTSPL3750 | B23: NOTUS SERVICES PRIVATE LIMITED | C23: courier | D23: 2026-09-30 | E23: 1700
A24: TTSPL7162 | B24: Optimizing Resources Private Limited | C24: courier | D24: 2026-09-30 | E24: 1600
A25: TTSPL7758 | B25: NUTRITIONALAB PRIVATE LIMITED | C25: courier | D25: 2026-09-30 | E25: 1999
... A29: TTSPL7773 | B29: NUTRITIONALAB PRIVATE LIMITED | C29: courier | D29: 2026-09-30 | E29: 1999
A31: C. Return credit notes the run will create automatically (laptops back at the warehouse in September, billed for the full month)
A32: Customer | B32: Credit (Rs) | C32: Laptops and credit period
A33: MOEVING URBAN TECHNOLOGIES PRIVATE LIMITED | B33: 9752.77 | C33: TTSPL3418 2026-09-11>2026-09-30, TTSPL3438 2026-09-23>2026-09-30, TTSPL3451 2026-09-23>2026-09-30, TTSPL3453 2026-09-23>2026-09-30, TTSPL3500 2026-09-23>2026-09-30, TTSPL3654 2026-09-23>2026-09-30, TTSPL3655 2026-09-29>2026-09-30, TTSPL4081 2026-09-11>2026-09-30, TTSPL5177 2026-09-23>2026-09-30, TTSPL5022 2026-09-29>2026-09-30, TTSPL4322 2026-09-23>2026-09-30, TTSPL5767 2026-09-23>2026-09-30, TTSPL4777 2026-09-11>2026-09-30
A34: Trailytics Global Services Private Limited | B34: 8097.3 | C34: TTSPL3467 2026-09-04>2026-09-30, TTSPL3718 2026-09-04>2026-09-30, TTSPL3077 2026-09-04>2026-09-30
A35: ASCENT RISK & RESILIENCE SOFTWARE PRIVATE LIMITED | B35: 7766.01 | C35: TTSPL4815 2026-09-26>2026-09-30, TTSPL4292 2026-09-15>2026-09-30, TTSPL4362 2026-09-15>2026-09-30, TTSPL4607 2026-09-26>2026-09-30, TTSPL6804 2026-09-26>2026-09-30, TTSPL6813 2026-09-26>2026-09-30, TTSPL6222 2026-09-26>2026-09-30, TTSPL6989 2026-09-15>2026-09-30
A36: Tagbin Services Pvt Ltd | B36: 6667.71 | C36: TTSPL3717 2026-09-08>2026-09-30, TTSPL7002 2026-09-08>2026-09-30, TTSPL4191 2026-09-08>2026-09-30
A37: Stylework Innovation Hub Pvt Ltd. | B37: 6251.93 | C37: TTSPL4996 2026-09-17>2026-09-30, TTSPL5451 2026-09-17>2026-09-30, TTSPL7258 2026-09-17>2026-09-30
A38: SelectAstro Private Limited | B38: 5277.91 | C38: TTSPL5506 2026-09-30>2026-09-30, TTSPL3488 2026-09-26>2026-09-30, TTSPL4098 2026-09-22>2026-09-30, TTSPL6047 2026-09-30>2026-09-30, TTSPL5326 2026-09-26>2026-09-30, TTSPL6618 2026-09-08>2026-09-30, TTSPL6943 2026-09-22>2026-09-30, TTSPL6978 2026-09-30>2026-09-30, TTSPL6063 2026-09-22>2026-09-30
A39: ERA BOTANICS PRIVATE LIMITED | B39: 4461.15 | C39: TTSPL4651 2026-09-18>2026-09-30, TTSPL4808 2026-09-18>2026-09-30, TTSPL5636 2026-09-18>2026-09-30, TTSPL5465 2026-09-18>2026-09-30, TTSPL6213 2026-09-18>2026-09-30
A40: VALENTA KPO PRIVATE LIMITED | B40: 3904.93 | C40: TTSPL2938 2026-09-27>2026-09-30, TTSPL3099 2026-09-19>2026-09-30, TTSPL3124 2026-09-19>2026-09-30, TTSPL3584 2026-09-19>2026-09-30, TTSPL2152 2026-09-19>2026-09-30
A41: BIZDATEUP TECHNOLOGIES PRIVATE LIMITED | B41: 3750 | C41: TTSPL4911 2026-09-15>2026-09-30, TTSPL3684 2026-09-25>2026-09-30, TTSPL3160 2026-09-15>2026-09-30, TTSPL1972 2026-09-15>2026-09-30, TTSPL5434 2026-09-25>2026-09-30, TTSPL4960 2026-09-25>2026-09-30, TTSPL7116 2026-09-15>2026-09-30, TTSPL7130 2026-09-25>2026-09-30, TTSPL7132 2026-09-25>2026-09-30
A42: MERVICE INFOTECH PRIVATE LIMITED | B42: 3447.7 | C42: TTSPL1866 2026-09-09>2026-09-30, TTSPL6734 2026-09-10>2026-09-30, TTSPL6085 2026-09-05>2026-09-30
A43: Nexthire LLP | B43: 3196.8 | C43: TTSPL4091 2026-09-04>2026-09-30, TTSPL2052 2026-09-10>2026-09-30, TTSPL2901 2026-09-04>2026-09-30, TTSPL2439 2026-09-10>2026-09-30
A44: Vaatun Technologies Private Limited | B44: 3150 | C44: TTSPL3466 2026-09-04>2026-09-30
... A77: COAL BEAUTY PRIVATE LIMITED | B77: 39.97 | C77: TTSPL1783 2026-09-30>2026-09-30
A79: D. Customers the run skips (no active rental)
...
